{
    "registryname":"biomass_generators",
    "localizedname":"生物质发电机",
    "color":"FFA500",
    "parts": [
        {
            "x": 0,
            "y": 0,
            "z": 0,
            "elements": [
                "modularmachinery:blockcontroller@2"
            ]
        },
        {
            "x": -3,
            "y": -2,
            "z": 5,
            "elements": [
                "contenttweaker:reinforced_mechine_casing@0"
            ]
        },
        {
            "x": 0,
            "y": -2,
            "z": 0,
            "elements": [
                "contenttweaker:reinforced_mechine_casing@0"
            ]
        },
        {
            "x": -1,
            "y": 2,
            "z": 0,
            "elements": [
                "contenttweaker:reinforced_mechine_casing@0"
            ]
        },
        {
            "x": 8,
            "y": 4,
            "z": -9,
            "elements": [
                "immersiveengineering:sheetmetal@9"
            ]
        },
        {
            "x": 11,
            "y": 2,
            "z": -9,
            "elements": [
                "immersiveengineering:sheetmetal@9"
            ]
        },
        {
            "x": 5,
            "y": -2,
            "z": 1,
            "elements": [
                "contenttweaker:reinforced_mechine_casing@0"
            ]
        },
        {
            "x": 11,
            "y": 7,
            "z": -3,
            "elements": [
                "modularmachinery:blockcasing@0"
            ]
        },
        {
            "x": 12,
            "y": -2,
            "z": 2,
            "elements": [
                "contenttweaker:reinforced_mechine_casing@0"
            ]
        },
        {
            "x": 13,
            "y": -2,
            "z": -9,
            "elements": [
                "contenttweaker:reinforced_mechine_casing@0"
            ]
        },
        {
            "x": 9,
            "y": 16,
            "z": 6,
            "elements": [
                "contenttweaker:reinforced_mechine_casing@0"
            ]
        },
        {
            "x": 8,
            "y": -1,
            "z": 7,
            "elements": [
                "contenttweaker:reinforced_mechine_casing@0"
            ]
        },
        {
            "x": 6,
            "y": 5,
            "z": 4,
            "elements": [
                "modularmachinery:blockcasing@0"
            ]
        },
        {
            "x": 12,
            "y": 0,
            "z": -4,
            "elements": [
                "modularmachinery:blockcasing@0"
            ]
        },
        {
            "x": 12,
            "y": 7,
            "z": -8,
            "elements": [
                "contenttweaker:reinforced_mechine_casing@0"
            ]
        },
        {
            "x": 8,
            "y": 9,
            "z": -3,
            "elements": [
                "contenttweaker:reinforced_mechine_casing@0"
            ]
        },
        {
            "x": 6,
            "y": 6,
            "z": 3,
            "elements": [
                "contenttweaker:reinforced_mechine_casing@0"
            ]
        },
        {
            "x": 9,
            "y": 2,
            "z": -4,
            "elements": [
                "modularmachinery:blockcasing@0"
            ]
        },
        {
            "x": 1,
            "y": 0,
            "z": 0,
            "elements": [
                "modularmachinery:blockinputbus"
            ]
        },
        {
            "x": -4,
            "y": -2,
            "z": 5,
            "elements": [
                "contenttweaker:reinforced_mechine_casing@0"
            ]
        },
        {
            "x": 1,
            "y": -2,
            "z": 0,
            "elements": [
                "contenttweaker:reinforced_mechine_casing@0"
            ]
        },
        {
            "x": 9,
            "y": 4,
            "z": -4,
            "elements": [
                "modularmachinery:blockcasing@0"
            ]
        },
        {
            "x": 8,
            "y": 11,
            "z": -3,
            "elements": [
                "contenttweaker:reinforced_mechine_casing@0"
            ]
        },
        {
            "x": 6,
            "y": 4,
            "z": 3,
            "elements": [
                "modularmachinery:blockcasing@0"
            ]
        },
        {
            "x": 11,
            "y": 0,
            "z": -9,
            "elements": [
                "immersiveengineering:sheetmetal@9"
            ]
        },
        {
            "x": 9,
            "y": 15,
            "z": 6,
            "elements": [
                "modularmachinery:blockcasing@0"
            ]
        },
        {
            "x": 8,
            "y": 5,
            "z": -3,
            "elements": [
                "modularmachinery:blockcasing@0"
            ]
        },
        {
            "x": -1,
            "y": 4,
            "z": 0,
            "elements": [
                "contenttweaker:reinforced_mechine_casing@0"
            ]
        },
        {
            "x": 9,
            "y": 0,
            "z": 7,
            "elements": [
                "modularmachinery:blockcasing@0"
            ]
        },
        {
            "x": 12,
            "y": 13,
            "z": 6,
            "elements": [
                "contenttweaker:reinforced_mechine_casing@0"
            ]
        },
        {
            "x": 8,
            "y": -2,
            "z": 7,
            "elements": [
                "contenttweaker:reinforced_mechine_casing@0"
            ]
        },
        {
            "x": 11,
            "y": -2,
            "z": -4,
            "elements": [
                "contenttweaker:reinforced_mechine_casing@0"
            ]
        },
        {
            "x": 12,
            "y": -2,
            "z": -9,
            "elements": [
                "contenttweaker:reinforced_mechine_casing@0"
            ]
        },
        {
            "x": 15,
            "y": 1,
            "z": 3,
            "elements": [
                "contenttweaker:reinforced_mechine_casing@0"
            ]
        },
        {
            "x": 9,
            "y": 7,
            "z": -8,
            "elements": [
                "contenttweaker:reinforced_mechine_casing@0"
            ]
        },
        {
            "x": 6,
            "y": 3,
            "z": 4,
            "elements": [
                "modularmachinery:blockcasing@0"
            ]
        },
        {
            "x": 11,
            "y": -2,
            "z": 2,
            "elements": [
                "contenttweaker:reinforced_mechine_casing@0"
            ]
        },
        {
            "x": 9,
            "y": 14,
            "z": 6,
            "elements": [
                "modularmachinery:blockcasing@0"
            ]
        },
        {
            "x": 6,
            "y": 1,
            "z": 4,
            "elements": [
                "modularmachinery:blockcasing@0"
            ]
        },
        {
            "x": 13,
            "y": 2,
            "z": -9,
            "elements": [
                "immersiveengineering:sheetmetal@9"
            ]
        },
        {
            "x": 8,
            "y": 4,
            "z": -4,
            "elements": [
                "contenttweaker:reinforced_mechine_casing@0"
            ]
        },
        {
            "x": 17,
            "y": -2,
            "z": 6,
            "elements": [
                "contenttweaker:reinforced_mechine_casing@0"
            ]
        },
        {
            "x": 15,
            "y": 15,
            "z": -1,
            "elements": [
                "contenttweaker:reinforced_mechine_casing@0"
            ]
        },
        {
            "x": -2,
            "y": -2,
            "z": 0,
            "elements": [
                "contenttweaker:reinforced_mechine_casing@0"
            ]
        },
        {
            "x": -1,
            "y": -2,
            "z": 5,
            "elements": [
                "contenttweaker:reinforced_mechine_casing@0"
            ]
        },
        {
            "x": 9,
            "y": 13,
            "z": 6,
            "elements": [
                "modularmachinery:blockcasing@0"
            ]
        },
        {
            "x": 6,
            "y": 2,
            "z": -1,
            "elements": [
                "modularmachinery:blockcasing@0"
            ]
        },
        {
            "x": 15,
            "y": 3,
            "z": 3,
            "elements": [
                "contenttweaker:reinforced_mechine_casing@0"
            ]
        },
        {
            "x": 14,
            "y": -2,
            "z": 7,
            "elements": [
                "contenttweaker:reinforced_mechine_casing@0"
            ]
        },
        {
            "x": 8,
            "y": -2,
            "z": -4,
            "elements": [
                "contenttweaker:reinforced_mechine_casing@0"
            ]
        },
        {
            "x": 6,
            "y": 3,
            "z": -1,
            "elements": [
                "modularmachinery:blockcasing@0"
            ]
        },
        {
            "x": 6,
            "y": 10,
            "z": 3,
            "elements": [
                "contenttweaker:reinforced_mechine_casing@0"
            ]
        },
        {
            "x": 8,
            "y": -2,
            "z": -1,
            "elements": [
                "contenttweaker:reinforced_mechine_casing@0"
            ]
        },
        {
            "x": 15,
            "y": 14,
            "z": -1,
            "elements": [
                "contenttweaker:reinforced_mechine_casing@0"
            ]
        },
        {
            "x": -1,
            "y": 0,
            "z": 0,
            "elements": [
                "modularmachinery:blockcasing@0"
            ]
        },
        {
            "x": 14,
            "y": 14,
            "z": 4,
            "elements": [
                "modularmachinery:blockcasing@0"
            ]
        },
        {
            "x": 3,
            "y": -2,
            "z": 0,
            "elements": [
                "contenttweaker:reinforced_mechine_casing@0"
            ]
        },
        {
            "x": 17,
            "y": -2,
            "z": 7,
            "elements": [
                "contenttweaker:reinforced_mechine_casing@0"
            ]
        },
        {
            "x": 5,
            "y": -1,
            "z": 4,
            "elements": [
                "modularmachinery:blockcasing@0"
            ]
        },
        {
            "x": 7,
            "y": 4,
            "z": -9,
            "elements": [
                "immersiveengineering:sheetmetal@9"
            ]
        },
        {
            "x": 15,
            "y": 5,
            "z": 3,
            "elements": [
                "contenttweaker:reinforced_mechine_casing@0"
            ]
        },
        {
            "x": 8,
            "y": 2,
            "z": -9,
            "elements": [
                "immersiveengineering:sheetmetal@9"
            ]
        },
        {
            "x": 12,
            "y": 6,
            "z": -8,
            "elements": [
                "contenttweaker:reinforced_mechine_casing@0"
            ]
        },
        {
            "x": 13,
            "y": 0,
            "z": -9,
            "elements": [
                "immersiveengineering:sheetmetal@9"
            ]
        },
        {
            "x": 16,
            "y": 0,
            "z": 2,
            "elements": [
                "modularmachinery:blockcasing@0"
            ]
        },
        {
            "x": 8,
            "y": -2,
            "z": 1,
            "elements": [
                "contenttweaker:reinforced_mechine_casing@0"
            ]
        },
        {
            "x": 1,
            "y": 4,
            "z": 0,
            "elements": [
                "contenttweaker:reinforced_mechine_casing@0"
            ]
        },
        {
            "x": 10,
            "y": -2,
            "z": -9,
            "elements": [
                "contenttweaker:reinforced_mechine_casing@0"
            ]
        },
        {
            "x": 8,
            "y": 7,
            "z": -3,
            "elements": [
                "contenttweaker:reinforced_mechine_casing@0"
            ]
        },
        {
            "x": 11,
            "y": -2,
            "z": 3,
            "elements": [
                "contenttweaker:reinforced_mechine_casing@0"
            ]
        },
        {
            "x": 6,
            "y": 8,
            "z": 3,
            "elements": [
                "contenttweaker:reinforced_mechine_casing@0"
            ]
        },
        {
            "x": 15,
            "y": 13,
            "z": -1,
            "elements": [
                "contenttweaker:reinforced_mechine_casing@0"
            ]
        },
        {
            "x": 12,
            "y": 5,
            "z": -8,
            "elements": [
                "contenttweaker:reinforced_mechine_vents@0"
            ]
        },
        {
            "x": 6,
            "y": 1,
            "z": -1,

            "elements": [
                "modularmachinery:blockcasing@0"
            ]
        },
        {
            "x": 8,
            "y": 2,
            "z": -4,
            "elements": [
                "contenttweaker:reinforced_mechine_casing@0"
            ]
        },
        {
            "x": 4,
            "y": -2,
            "z": 0,
            "elements": [
                "contenttweaker:reinforced_mechine_casing@0"
            ]
        },
        {
            "x": 6,
            "y": 7,
            "z": -1,
            "elements": [
                "contenttweaker:reinforced_mechine_casing@0"
            ]
        },
        {
            "x": 4,
            "y": 0,
            "z": 0,

            "elements": [
                "modularmachinery:blockcasing@0"
            ]
        },
        {
            "x": 1,
            "y": -2,
            "z": 5,
            "elements": [
                "contenttweaker:reinforced_mechine_casing@0"
            ]
        },
        {
            "x": -1,
            "y": -2,
            "z": -4,
            "elements": [
                "contenttweaker:reinforced_mechine_casing@0"
            ]
        },
        {
            "x": 14,
            "y": 16,
            "z": 4,
            "elements": [
                "contenttweaker:reinforced_mechine_casing@0"
            ]
        },
        {
            "x": 2,
            "y": 4,
            "z": 0,
            "elements": [
                "contenttweaker:reinforced_mechine_casing@0"
            ]
        },
        {
            "x": 17,
            "y": -2,
            "z": -1,
            "elements": [
                "contenttweaker:reinforced_mechine_casing@0"
            ]
        },
        {
            "x": 5,
            "y": -2,
            "z": 7,
            "elements": [
                "contenttweaker:reinforced_mechine_casing@0"
            ]
        },
        {
            "x": 11,
            "y": 15,
            "z": -4,

            "elements": [
                "modularmachinery:blockcasing@0"
            ]
        },
        {
            "x": 6,
            "y": 6,
            "z": -1,
            "elements": [
                "contenttweaker:reinforced_mechine_casing@0"
            ]
        },
        {
            "x": 1,
            "y": -2,
            "z": -9,
            "elements": [
                "contenttweaker:reinforced_mechine_casing@0"
            ]
        },
        {
            "x": 17,
            "y": -2,
            "z": -2,
            "elements": [
                "contenttweaker:reinforced_mechine_casing@0"
            ]
        },
        {
            "x": 13,
            "y": 4,
            "z": -9,
            "elements": [
                "immersiveengineering:sheetmetal@9"
            ]
        },
        {
            "x": 15,
            "y": 0,
            "z": -2,

            "elements": [
                "modularmachinery:blockcasing@0"
            ]
        },
        {
            "x": 12,
            "y": 7,
            "z": -2,

            "elements": [
                "modularmachinery:blockcasing@0"
            ]
        },
        {
            "x": -3,
            "y": -2,
            "z": 0,
            "elements": [
                "contenttweaker:reinforced_mechine_casing@0"
            ]
        },
        {
            "x": -4,
            "y": -2,
            "z": -4,
            "elements": [
                "contenttweaker:reinforced_mechine_casing@0"
            ]
        },
        {
            "x": 14,
            "y": -2,
            "z": -1,
            "elements": [
                "contenttweaker:reinforced_mechine_casing@0"
            ]
        },
        {
            "x": 12,
            "y": 6,
            "z": -2,

            "elements": [
                "modularmachinery:blockcasing@0"
            ]
        },
        {
            "x": 6,
            "y": 4,
            "z": -1,

            "elements": [
                "modularmachinery:blockcasing@0"
            ]
        },
        {
            "x": 5,
            "y": -2,
            "z": 3,
            "elements": [
                "contenttweaker:reinforced_mechine_casing@0"
            ]
        },
        {
            "x": 11,
            "y": 13,
            "z": -4,

            "elements": [
                "modularmachinery:blockcasing@0"
            ]
        },
        {
            "x": 15,
            "y": -2,
            "z": 2,
            "elements": [
                "contenttweaker:reinforced_mechine_casing@0"
            ]
        },
        {
            "x": 6,
            "y": 5,
            "z": -1,

            "elements": [
                "modularmachinery:blockcasing@0"
            ]
        },
        {
            "x": 14,
            "y": -2,
            "z": 8,
            "elements": [
                "contenttweaker:reinforced_mechine_casing@0"
            ]
        },
        {
            "x": 17,
            "y": -2,
            "z": -8,
            "elements": [
                "contenttweaker:reinforced_mechine_casing@0"
            ]
        },
        {
            "x": -2,
            "y": 0,
            "z": 0,

            "elements": [
                "modularmachinery:blockcasing@0"
            ]
        },
        {
            "x": 12,
            "y": 15,
            "z": 6,
            "elements": [
                "contenttweaker:reinforced_mechine_casing@0"
            ]
        },
        {
            "x": 5,
            "y": -2,
            "z": 6,
            "elements": [
                "contenttweaker:reinforced_mechine_casing@0"
            ]
        },
        {
            "x": 6,
            "y": 2,
            "z": 3,

            "elements": [
                "modularmachinery:blockcasing@0"
            ]
        },
        {
            "x": 11,
            "y": -2,
            "z": -1,
            "elements": [
                "contenttweaker:reinforced_mechine_casing@0"
            ]
        },
        {
            "x": 14,
            "y": 13,
            "z": 3,

            "elements": [
                "modularmachinery:blockcasing@0"
            ]
        },
        {
            "x": 5,
            "y": 2,
            "z": 0,

            "elements": [
                "modularmachinery:blockcasing@0"
            ]
        },
        {
            "x": 6,
            "y": 11,
            "z": -1,
            "elements": [
                "contenttweaker:reinforced_mechine_casing@0"
            ]
        },
        {
            "x": 8,
            "y": 3,
            "z": -3,

            "elements": [
                "modularmachinery:blockcasing@0"
            ]
        },
        {
            "x": 15,
            "y": 15,
            "z": 3,
            "elements": [
                "contenttweaker:reinforced_mechine_casing@0"
            ]
        },
        {
            "x": 8,
            "y": -2,
            "z": 3,
            "elements": [
                "contenttweaker:reinforced_mechine_casing@0"
            ]
        },
        {
            "x": 14,
            "y": -2,
            "z": 2,
            "elements": [
                "contenttweaker:reinforced_mechine_casing@0"
            ]
        },
        {
            "x": 6,
            "y": 10,
            "z": -1,
            "elements": [
                "contenttweaker:reinforced_mechine_casing@0"
            ]
        },
        {
            "x": -4,
            "y": -2,
            "z": 1,
            "elements": [
                "contenttweaker:reinforced_mechine_casing@0"
            ]
        },
        {
            "x": 11,
            "y": -2,
            "z": 8,
            "elements": [
                "contenttweaker:reinforced_mechine_casing@0"
            ]
        },
        {
            "x": 12,
            "y": 14,
            "z": 6,
            "elements": [
                "contenttweaker:reinforced_mechine_casing@0"
            ]
        },
        {
            "x": 15,
            "y": 1,
            "z": 2,

            "elements": [
                "modularmachinery:blockcasing@0"
            ]
        },
        {
            "x": -2,
            "y": -2,
            "z": 5,
            "elements": [
                "contenttweaker:reinforced_mechine_casing@0"
            ]
        },
        {
            "x": 13,
            "y": 15,
            "z": 5,

            "elements": [
                "modularmachinery:blockcasing@0"
            ]
        },
        {
            "x": 5,
            "y": -1,
            "z": -1,

            "elements": [
                "modularmachinery:blockcasing@0"
            ]
        },
        {
            "x": 8,
            "y": 1,
            "z": -3,

            "elements": [
                "modularmachinery:blockcasing@0"
            ]
        },
        {
            "x": -2,
            "y": -2,
            "z": -9,
            "elements": [
                "contenttweaker:reinforced_mechine_casing@0"
            ]
        },
        {
            "x": 15,
            "y": 2,
            "z": 2,

            "elements": [
                "modularmachinery:blockcasing@0"
            ]
        },
        {
            "x": 2,
            "y": -2,
            "z": 7,
            "elements": [
                "contenttweaker:reinforced_mechine_casing@0"
            ]
        },
        {
            "x": 12,
            "y": 16,
            "z": 6,
            "elements": [
                "contenttweaker:reinforced_mechine_casing@0"
            ]
        },
        {
            "x": 14,
            "y": 15,
            "z": 3,

            "elements": [
                "modularmachinery:blockcasing@0"
            ]
        },
        {
            "x": 15,
            "y": 13,
            "z": 3,
            "elements": [
                "contenttweaker:reinforced_mechine_casing@0"
            ]
        },
        {
            "x": 6,
            "y": 9,
            "z": -1,
            "elements": [
                "contenttweaker:reinforced_mechine_casing@0"
            ]
        },
        {
            "x": 17,
            "y": -2,
            "z": 2,
            "elements": [
                "contenttweaker:reinforced_mechine_casing@0"
            ]
        },
        {
            "x": 6,
            "y": 8,
            "z": -1,
            "elements": [
                "contenttweaker:reinforced_mechine_casing@0"
            ]
        },
        {
            "x": 5,
            "y": 4,
            "z": 0,

            "elements": [
                "modularmachinery:blockcasing@0"
            ]
        },
        {
            "x": 5,
            "y": -2,
            "z": -1,
            "elements": [
                "contenttweaker:reinforced_mechine_casing@0"
            ]
        },
        {
            "x": 5,
            "y": -2,
            "z": -4,
            "elements": [
                "contenttweaker:reinforced_mechine_casing@0"
            ]
        },
        {
            "x": 15,
            "y": 3,
            "z": 2,

            "elements": [
                "modularmachinery:blockcasing@0"
            ]
        },
        {
            "x": -4,
            "y": -2,
            "z": -7,
            "elements": [
                "contenttweaker:reinforced_mechine_casing@0"
            ]
        },
        {
            "x": 14,
            "y": -2,
            "z": -2,
            "elements": [
                "contenttweaker:reinforced_mechine_casing@0"
            ]
        },
        {
            "x": 6,
            "y": 13,
            "z": 1,

            "elements": [
                "modularmachinery:blockcasing@0"
            ]
        },
        {
            "x": 15,
            "y": 5,
            "z": -1,
            "elements": [
                "contenttweaker:reinforced_mechine_casing@0"
            ]
        },
        {
            "x": 12,
            "y": -2,
            "z": -6,
            "elements": [
                "contenttweaker:reinforced_mechine_casing@0"
            ]
        },
        {
            "x": 6,
            "y": 12,
            "z": -1,
            "elements": [
                "contenttweaker:reinforced_mechine_casing@0"
            ]
        },
        {
            "x": 5,
            "y": -2,
            "z": 5,
            "elements": [
                "contenttweaker:reinforced_mechine_casing@0"
            ]
        },
        {
            "x": 13,
            "y": 3,
            "z": -7,
            "elements": [
                "immersiveengineering:sheetmetal@9"
            ]
        },
        {
            "x": 4,
            "y": 0,
            "z": 3,
            "elements": [
                "contenttweaker:reinforced_mechine_casing@0"
            ]
        },
        {
            "x": 6,
            "y": -2,
            "z": 3,
            "elements": [
                "contenttweaker:reinforced_mechine_casing@0"
            ]
        },
        {
            "x": 3,
            "y": -2,
            "z": -4,
            "elements": [
                "contenttweaker:reinforced_mechine_casing@0"
            ]
        },
        {
            "x": 15,
            "y": 15,
            "z": 0,

            "elements": [
                "modularmachinery:blockcasing@0"
            ]
        },
        {
            "x": 10,
            "y": 7,
            "z": -7,
            "elements": [
                "contenttweaker:reinforced_mechine_casing@0"
            ]
        },
        {
            "x": -1,
            "y": -2,
            "z": -8,
            "elements": [
                "contenttweaker:reinforced_mechine_casing@0"
            ]
        },
        {
            "x": 6,
            "y": 13,
            "z": -1,

            "elements": [
                "modularmachinery:blockcasing@0"
            ]
        },
        {
            "x": 6,
            "y": 12,
            "z": 1,

            "elements": [
                "modularmachinery:blockcasing@0"
            ]
        },
        {
            "x": 15,
            "y": 4,
            "z": -1,
            "elements": [
                "contenttweaker:reinforced_mechine_casing@0"
            ]
        },
        {
            "x": 5,
            "y": -2,
            "z": 8,
            "elements": [
                "contenttweaker:reinforced_mechine_casing@0"
            ]
        },
        {
            "x": 14,
            "y": -2,
            "z": -7,
            "elements": [
                "contenttweaker:reinforced_mechine_casing@0"
            ]
        },
        {
            "x": 12,
            "y": 4,
            "z": -7,
            "elements": [
                "immersiveengineering:sheetmetal@9"
            ]
        },
        {
            "x": 13,
            "y": 2,
            "z": -7,
            "elements": [
                "immersiveengineering:sheetmetal@9"
            ]
        },
        {
            "x": 7,
            "y": -2,
            "z": 0,
            "elements": [
                "contenttweaker:reinforced_mechine_casing@0"
            ]
        },
        {
            "x": 5,
            "y": -2,
            "z": -9,
            "elements": [
                "contenttweaker:reinforced_mechine_casing@0"
            ]
        },
        {
            "x": 6,
            "y": 14,
            "z": -1,

            "elements": [
                "modularmachinery:blockcasing@0"
            ]
        },
        {
            "x": 15,
            "y": 13,
            "z": 0,

            "elements": [
                "modularmachinery:blockcasing@0"
            ]
        },
        {
            "x": -1,
            "y": -2,
            "z": 8,
            "elements": [
                "contenttweaker:reinforced_mechine_casing@0"
            ]
        },
        {
            "x": 4,
            "y": -2,
            "z": 5,
            "elements": [
                "contenttweaker:reinforced_mechine_casing@0"
            ]
        },
        {
            "x": 15,
            "y": -2,
            "z": -6,
            "elements": [
                "contenttweaker:reinforced_mechine_casing@0"
            ]
        },
        {
            "x": 2,
            "y": -2,
            "z": -8,
            "elements": [
                "contenttweaker:reinforced_mechine_casing@0"
            ]
        },
        {
            "x": 12,
            "y": 3,
            "z": -7,
            "elements": [
                "immersiveengineering:sheetmetal@9"
            ]
        },
        {
            "x": 12,
            "y": 13,
            "z": -2,

            "elements": [
                "modularmachinery:blockcasing@0"
            ]
        },
        {
            "x": 0,
            "y": -2,
            "z": -4,
            "elements": [
                "contenttweaker:reinforced_mechine_casing@0"
            ]
        },
        {
            "x": 2,
            "y": -2,
            "z": 8,
            "elements": [
                "contenttweaker:reinforced_mechine_casing@0"
            ]
        },
        {
            "x": 6,
            "y": 0,
            "z": 5,

            "elements": [
                "modularmachinery:blockcasing@0"
            ]
        },
        {
            "x": 12,
            "y": 5,
            "z": -7,
            "elements": [
                "immersiveengineering:sheetmetal@9"
            ]
        },
        {
            "x": 13,
            "y": 4,
            "z": -7,
            "elements": [
                "immersiveengineering:sheetmetal@9"
            ]
        },
        {
            "x": 4,
            "y": -2,
            "z": -9,
            "elements": [
                "contenttweaker:reinforced_mechine_casing@0"
            ]
        },
        {
            "x": 12,
            "y": 2,
            "z": -7,
            "elements": [
                "immersiveengineering:sheetmetal@9"
            ]
        },
        {
            "x": 16,
            "y": 0,
            "z": 1,

            "elements": [
                "modularmachinery:blockcasing@0"
            ]
        },
        {
            "x": 6,
            "y": 15,
            "z": -1,

            "elements": [
                "modularmachinery:blockcasing@0"
            ]
        },
        {
            "x": 12,
            "y": 1,
            "z": -7,
            "elements": [
                "immersiveengineering:sheetmetal@9"
            ]
        },
        {
            "x": 15,
            "y": 0,
            "z": -1,

            "elements": [
                "modularmachinery:blockcasing@0"
            ]
        },
        {
            "x": 6,
            "y": 14,
            "z": -2,

            "elements": [
                "modularmachinery:blockcasing@0"
            ]
        },
        {
            "x": 12,
            "y": 10,
            "z": -2,

            "elements": [
                "modularmachinery:blockcasing@0"
            ]
        },
        {
            "x": 10,
            "y": 7,
            "z": -6,
            "elements": [
                "contenttweaker:reinforced_mechine_casing@0"
            ]
        },
        {
            "x": 7,
            "y": -2,
            "z": 5,
            "elements": [
                "contenttweaker:reinforced_mechine_casing@0"
            ]
        },
        {
            "x": 7,
            "y": -2,
            "z": -9,
            "elements": [
                "contenttweaker:reinforced_mechine_casing@0"
            ]
        },
        {
            "x": 1,
            "y": -2,
            "z": -4,
            "elements": [
                "contenttweaker:reinforced_mechine_casing@0"
            ]
        },
        {
            "x": 15,
            "y": 1,
            "z": 1,

            "elements": [
                "modularmachinery:blockcasing@0"
            ]
        },
        {
            "x": 6,
            "y": 15,
            "z": -2,

            "elements": [
                "modularmachinery:blockcasing@0"
            ]
        },
        {
            "x": 4,
            "y": 4,
            "z": 0,
            "elements": [
                "contenttweaker:reinforced_mechine_casing@0"
            ]
        },
        {
            "x": 6,
            "y": 16,
            "z": -1,
            "elements": [
                "contenttweaker:reinforced_mechine_casing@0"
            ]
        },
        {
            "x": 6,
            "y": 13,
            "z": -2,

            "elements": [
                "modularmachinery:blockcasing@0"
            ]
        },
        {
            "x": 15,
            "y": 1,
            "z": -1,
            "elements": [
                "contenttweaker:reinforced_mechine_casing@0"
            ]
        },
        {
            "x": 8,
            "y": -2,
            "z": -8,
            "elements": [
                "contenttweaker:reinforced_mechine_casing@0"
            ]
        },
        {
            "x": 12,
            "y": 0,
            "z": -7,
            "elements": [
                "immersiveengineering:sheetmetal@9"
            ]
        },
        {
            "x": 15,
            "y": -2,
            "z": 1,
            "elements": [
                "contenttweaker:reinforced_mechine_casing@0"
            ]
        },
        {
            "x": 12,
            "y": 8,
            "z": -2,

            "elements": [
                "modularmachinery:blockcasing@0"
            ]
        },
        {
            "x": 9,
            "y": 1,
            "z": 6,

            "elements": [
                "modularmachinery:blockcasing@0"
            ]
        },
        {
            "x": -4,
            "y": -2,
            "z": 3,
            "elements": [
                "contenttweaker:reinforced_mechine_casing@0"
            ]
        },
        {
            "x": 12,
            "y": 9,
            "z": -2,

            "elements": [
                "modularmachinery:blockcasing@0"
            ]
        },
        {
            "x": 6,
            "y": 16,
            "z": -2,
            "elements": [
                "contenttweaker:reinforced_mechine_casing@0"
            ]
        },
        {
            "x": 9,
            "y": -2,
            "z": 0,
            "elements": [
                "contenttweaker:reinforced_mechine_casing@0"
            ]
        },
        {
            "x": 12,
            "y": 12,
            "z": -2,

            "elements": [
                "modularmachinery:blockcasing@0"
            ]
        },
        {
            "x": 2,
            "y": -2,
            "z": 5,
            "elements": [
                "contenttweaker:reinforced_mechine_casing@0"
            ]
        },
        {
            "x": 8,
            "y": 2,
            "z": 5,

            "elements": [
                "modularmachinery:blockcasing@0"
            ]
        },
        {
            "x": 11,
            "y": -1,
            "z": -7,
            "elements": [
                "ic2:fence@0"
            ]
        },
        {
            "x": 15,
            "y": 2,
            "z": -1,
            "elements": [
                "contenttweaker:reinforced_mechine_casing@0"
            ]
        },
        {
            "x": 15,
            "y": 3,
            "z": -1,
            "elements": [
                "contenttweaker:reinforced_mechine_casing@0"
            ]
        },
        {
            "x": 15,
            "y": 3,
            "z": 1,
            "elements": [
                "contenttweaker:reinforced_mechine_vents@0"
            ]
        },
        {
            "x": 11,
            "y": -2,
            "z": -7,
            "elements": [
                "contenttweaker:reinforced_mechine_casing@0"
            ]
        },
        {
            "x": 2,
            "y": -2,
            "z": -4,
            "elements": [
                "contenttweaker:reinforced_mechine_casing@0"
            ]
        },
        {
            "x": 8,
            "y": -2,
            "z": 6,
            "elements": [
                "contenttweaker:reinforced_mechine_casing@0"
            ]
        },
        {
            "x": 8,
            "y": -1,
            "z": 6,

            "elements": [
                "modularmachinery:blockcasing@0"
            ]
        },
        {
            "x": 12,
            "y": 11,
            "z": -2,

            "elements": [
                "modularmachinery:blockcasing@0"
            ]
        },
        {
            "x": 8,
            "y": -2,
            "z": 8,
            "elements": [
                "contenttweaker:reinforced_mechine_casing@0"
            ]
        },
        {
            "x": 15,
            "y": 2,
            "z": 1,
            "elements": [
                "contenttweaker:reinforced_mechine_vents@0"
            ]
        },
        {
            "x": 2,
            "y": -2,
            "z": -9,
            "elements": [
                "contenttweaker:reinforced_mechine_casing@0"
            ]
        },
        {
            "x": 3,
            "y": -2,
            "z": 3,
            "elements": [
                "contenttweaker:reinforced_mechine_casing@0"
            ]
        },
        {
            "x": 6,
            "y": -2,
            "z": 0,
            "elements": [
                "contenttweaker:reinforced_mechine_casing@0"
            ]
        },
        {
            "x": 17,
            "y": -2,
            "z": 8,
            "elements": [
                "contenttweaker:reinforced_mechine_casing@0"
            ]
        },
        {
            "x": 8,
            "y": 4,
            "z": 5,

            "elements": [
                "modularmachinery:blockcasing@0"
            ]
        },
        {
            "x": 11,
            "y": -2,
            "z": 6,
            "elements": [
                "contenttweaker:reinforced_mechine_casing@0"
            ]
        },
        {
            "x": 12,
            "y": 5,
            "z": 6,
            "elements": [
                "contenttweaker:reinforced_mechine_casing@0"
            ]
        },
        {
            "x": 9,
            "y": 1,
            "z": -8,
            "elements": [
                "immersiveengineering:sheetmetal@9"
            ]
        },
        {
            "x": 7,
            "y": 2,
            "z": -9,
            "elements": [
                "immersiveengineering:sheetmetal@9"
            ]
        },
        {
            "x": 9,
            "y": 3,
            "z": 6,

            "elements": [
                "modularmachinery:blockcasing@0"
            ]
        },
        {
            "x": 12,
            "y": 0,
            "z": 7,
            "elements": [
                "contenttweaker:reinforced_mechine_casing@0"
            ]
        },
        {
            "x": 12,
            "y": 4,
            "z": 6,
            "elements": [
                "contenttweaker:reinforced_mechine_casing@0"
            ]
        },
        {
            "x": 14,
            "y": -2,
            "z": -8,
            "elements": [
                "contenttweaker:reinforced_mechine_casing@0"
            ]
        },
        {
            "x": 9,
            "y": -2,
            "z": -9,
            "elements": [
                "contenttweaker:reinforced_mechine_casing@0"
            ]
        },
        {
            "x": 17,
            "y": -2,
            "z": 1,
            "elements": [
                "contenttweaker:reinforced_mechine_casing@0"
            ]
        },
        {
            "x": 7,
            "y": 0,
            "z": -9,
            "elements": [
                "immersiveengineering:sheetmetal@9"
            ]
        },
        {
            "x": 9,
            "y": 2,
            "z": 6,

            "elements": [
                "modularmachinery:blockcasing@0"
            ]
        },
        {
            "x": 8,
            "y": 0,
            "z": -4,

            "elements": [
                "modularmachinery:blockcasing@0"
            ]
        },
        {
            "x": 11,
            "y": 11,
            "z": 5,

            "elements": [
                "modularmachinery:blockcasing@0"
            ]
        },
        {
            "x": 12,
            "y": 0,
            "z": -8,
            "elements": [
                "modularmachinery:blockfluidinputhatch"
            ]
        },
        {
            "x": 6,
            "y": 6,
            "z": 1,

            "elements": [
                "modularmachinery:blockcasing@0"
            ]
        },
        {
            "x": 9,
            "y": 2,
            "z": -8,
            "elements": [
                "immersiveengineering:sheetmetal@9"
            ]
        },
        {
            "x": 2,
            "y": -2,
            "z": 3,
            "elements": [
                "contenttweaker:reinforced_mechine_casing@0"
            ]
        },
        {
            "x": 9,
            "y": 5,
            "z": 6,

            "elements": [
                "modularmachinery:blockcasing@0"
            ]
        },
        {
            "x": 14,
            "y": -2,
            "z": 6,
            "elements": [
                "contenttweaker:reinforced_mechine_casing@0"
            ]
        },
        {
            "x": 12,
            "y": 0,
            "z": 6,

            "elements": [
                "modularmachinery:blockcasing@0"
            ]
        },
        {
            "x": 11,
            "y": -2,
            "z": 7,
            "elements": [
                "contenttweaker:reinforced_mechine_casing@0"
            ]
        },
        {
            "x": 4,
            "y": -2,
            "z": -4,
            "elements": [
                "contenttweaker:reinforced_mechine_casing@0"
            ]
        },
        {
            "x": 12,
            "y": 3,
            "z": 6,
            "elements": [
                "contenttweaker:reinforced_mechine_casing@0"
            ]
        },
        {
            "x": 8,
            "y": 15,
            "z": 5,

            "elements": [
                "modularmachinery:blockcasing@0"
            ]
        },
        {
            "x": 11,
            "y": 13,
            "z": 5,

            "elements": [
                "modularmachinery:blockcasing@0"
            ]
        },
        {
            "x": 14,
            "y": -2,
            "z": 1,
            "elements": [
                "contenttweaker:reinforced_mechine_casing@0"
            ]
        },
        {
            "x": 7,
            "y": -2,
            "z": -4,
            "elements": [
                "contenttweaker:reinforced_mechine_casing@0"
            ]
        },
        {
            "x": 8,
            "y": 0,
            "z": -9,
            "elements": [
                "immersiveengineering:sheetmetal@9"
            ]
        },
        {
            "x": 6,
            "y": 3,
            "z": -2,

            "elements": [
                "modularmachinery:blockcasing@0"
            ]
        },
        {
            "x": 17,
            "y": -2,
            "z": -7,
            "elements": [
                "contenttweaker:reinforced_mechine_casing@0"
            ]
        },
        {
            "x": 8,
            "y": -2,
            "z": -2,
            "elements": [
                "contenttweaker:reinforced_mechine_casing@0"
            ]
        },
        {
            "x": 6,
            "y": 7,
            "z": 1,
            "elements": [
                "contenttweaker:reinforced_mechine_vents@0"
            ]
        },
        {
            "x": 9,
            "y": 0,
            "z": -8,
            "elements": [
                "immersiveengineering:sheetmetal@9"
            ]
        },
        {
            "x": 12,
            "y": -2,
            "z": 0,
            "elements": [
                "contenttweaker:reinforced_mechine_casing@0"
            ]
        },
        {
            "x": 0,
            "y": -2,
            "z": -9,
            "elements": [
                "contenttweaker:reinforced_mechine_casing@0"
            ]
        },
        {
            "x": -3,
            "y": -2,
            "z": 3,
            "elements": [
                "contenttweaker:reinforced_mechine_casing@0"
            ]
        },
        {
            "x": 11,
            "y": -1,
            "z": 7,

            "elements": [
                "modularmachinery:blockcasing@0"
            ]
        },
        {
            "x": 9,
            "y": 4,
            "z": 6,

            "elements": [
                "modularmachinery:blockcasing@0"
            ]
        },
        {
            "x": 12,
            "y": 2,
            "z": 6,
            "elements": [
                "contenttweaker:reinforced_mechine_casing@0"
            ]
        },
        {
            "x": 6,
            "y": 4,
            "z": -2,

            "elements": [
                "modularmachinery:blockcasing@0"
            ]
        },
        {
            "x": 8,
            "y": -1,
            "z": -5,
            "elements": [
                "contenttweaker:reinforced_mechine_casing@0"
            ]
        },
        {
            "x": 11,
            "y": 7,
            "z": 5,

            "elements": [
                "modularmachinery:blockcasing@0"
            ]
        },
        {
            "x": 6,
            "y": 8,
            "z": 1,
            "elements": [
                "contenttweaker:reinforced_mechine_vents@0"
            ]
        },
        {
            "x": 12,
            "y": 1,
            "z": 6,
            "elements": [
                "contenttweaker:reinforced_mechine_casing@0"
            ]
        },
        {
            "x": 11,
            "y": -2,
            "z": 1,
            "elements": [
                "contenttweaker:reinforced_mechine_casing@0"
            ]
        },
        {
            "x": -3,
            "y": -2,
            "z": -4,
            "elements": [
                "contenttweaker:reinforced_mechine_casing@0"
            ]
        },
        {
            "x": 13,
            "y": 5,
            "z": -7,
            "elements": [
                "immersiveengineering:sheetmetal@9"
            ]
        },
        {
            "x": 9,
            "y": 5,
            "z": -8,
            "elements": [
                "immersiveengineering:sheetmetal@9"
            ]
        },
        {
            "x": 6,
            "y": 9,
            "z": 1,
            "elements": [
                "contenttweaker:reinforced_mechine_vents@0"
            ]
        },
        {
            "x": 11,
            "y": -2,
            "z": -2,
            "elements": [
                "contenttweaker:reinforced_mechine_casing@0"
            ]
        },
        {
            "x": 6,
            "y": 5,
            "z": -2,

            "elements": [
                "modularmachinery:blockcasing@0"
            ]
        },
        {
            "x": 8,
            "y": 13,
            "z": 5,

            "elements": [
                "modularmachinery:blockcasing@0"
            ]
        },
        {
            "x": 11,
            "y": -1,
            "z": -5,

            "elements": [
                "modularmachinery:blockcasing@0"
            ]
        },
        {
            "x": 3,
            "y": -2,
            "z": -9,
            "elements": [
                "contenttweaker:reinforced_mechine_casing@0"
            ]
        },
        {
            "x": 6,
            "y": 2,
            "z": -2,

            "elements": [
                "modularmachinery:blockcasing@0"
            ]
        },
        {
            "x": 0,
            "y": -2,
            "z": 3,
            "elements": [
                "contenttweaker:reinforced_mechine_casing@0"
            ]
        },
        {
            "x": 11,
            "y": 9,
            "z": 5,

            "elements": [
                "modularmachinery:blockcasing@0"
            ]
        },
        {
            "x": -4,
            "y": -2,
            "z": -8,
            "elements": [
                "contenttweaker:reinforced_mechine_casing@0"
            ]
        },
        {
            "x": 9,
            "y": 4,
            "z": -8,
            "elements": [
                "immersiveengineering:sheetmetal@9"
            ]
        },
        {
            "x": 15,
            "y": 4,
            "z": 1,
            "elements": [
                "contenttweaker:reinforced_mechine_vents@0"
            ]
        },
        {
            "x": -2,
            "y": -2,
            "z": -4,
            "elements": [
                "contenttweaker:reinforced_mechine_casing@0"
            ]
        },
        {
            "x": 6,
            "y": 10,
            "z": 1,
            "elements": [
                "contenttweaker:reinforced_mechine_vents@0"
            ]
        },
        {
            "x": 6,
            "y": 1,
            "z": -2,

            "elements": [
                "modularmachinery:blockcasing@0"
            ]
        },
        {
            "x": 17,
            "y": -2,
            "z": -6,
            "elements": [
                "contenttweaker:reinforced_mechine_casing@0"
            ]
        },
        {
            "x": 9,
            "y": 3,
            "z": -8,
            "elements": [
                "immersiveengineering:sheetmetal@9"
            ]
        },
        {
            "x": 15,
            "y": 5,
            "z": 1,

            "elements": [
                "modularmachinery:blockcasing@0"
            ]
        },
        {
            "x": 11,
            "y": -2,
            "z": -8,
            "elements": [
                "contenttweaker:reinforced_mechine_casing@0"
            ]
        },
        {
            "x": 15,
            "y": -2,
            "z": -7,
            "elements": [
                "contenttweaker:reinforced_mechine_casing@0"
            ]
        },
        {
            "x": -1,
            "y": -2,
            "z": 3,
            "elements": [
                "contenttweaker:reinforced_mechine_casing@0"
            ]
        },
        {
            "x": 8,
            "y": 11,
            "z": 5,
            "elements": [
                "contenttweaker:reinforced_mechine_casing@0"
            ]
        },
        {
            "x": 6,
            "y": -2,
            "z": -9,
            "elements": [
                "contenttweaker:reinforced_mechine_casing@0"
            ]
        },
        {
            "x": 6,
            "y": 11,
            "z": 1,
            "elements": [
                "contenttweaker:reinforced_mechine_vents@0"
            ]
        },
        {
            "x": 13,
            "y": 2,
            "z": 5,

            "elements": [
                "modularmachinery:blockcasing@0"
            ]
        },
        {
            "x": 3,
            "y": 3,
            "z": 2,
            "elements": [
                "contenttweaker:reinforced_mechine_casing@0"
            ]
        },
        {
            "x": 13,
            "y": 1,
            "z": 5,

            "elements": [
                "modularmachinery:blockcasing@0"
            ]
        },
        {
            "x": 17,
            "y": -2,
            "z": -5,
            "elements": [
                "contenttweaker:reinforced_mechine_casing@0"
            ]
        },
        {
            "x": 7,
            "y": -2,
            "z": 6,
            "elements": [
                "contenttweaker:reinforced_mechine_casing@0"
            ]
        },
        {
            "x": 6,
            "y": -2,
            "z": -7,
            "elements": [
                "contenttweaker:reinforced_mechine_casing@0"
            ]
        },
        {
            "x": 16,
            "y": 0,
            "z": 0,

            "elements": [
                "modularmachinery:blockcasing@0"
            ]
        },
        {
            "x": 5,
            "y": -2,
            "z": -2,
            "elements": [
                "contenttweaker:reinforced_mechine_casing@0"
            ]
        },
        {
            "x": 9,
            "y": 5,
            "z": -9,
            "elements": [
                "immersiveengineering:sheetmetal@9"
            ]
        },
        {
            "x": 13,
            "y": 13,
            "z": 4,

            "elements": [
                "modularmachinery:blockcasing@0"
            ]
        },
        {
            "x": 15,
            "y": -2,
            "z": 0,
            "elements": [
                "contenttweaker:reinforced_mechine_casing@0"
            ]
        },
        {
            "x": 10,
            "y": 6,
            "z": 5,

            "elements": [
                "modularmachinery:blockcasing@0"
            ]
        },
        {
            "x": 5,
            "y": 1,
            "z": -1,
            "elements": [
                "contenttweaker:reinforced_mechine_casing@0"
            ]
        },
        {
            "x": 8,
            "y": 4,
            "z": 6,
            "elements": [
                "contenttweaker:reinforced_mechine_casing@0"
            ]
        },
        {
            "x": 8,
            "y": 0,
            "z": 6,

            "elements": [
                "modularmachinery:blockcasing@0"
            ]
        },
        {
            "x": 9,
            "y": -2,
            "z": 4,
            "elements": [
                "contenttweaker:reinforced_mechine_casing@0"
            ]
        },
        {
            "x": 10,
            "y": -2,
            "z": 6,
            "elements": [
                "contenttweaker:reinforced_mechine_casing@0"
            ]
        },
        {
            "x": 7,
            "y": 14,
            "z": 5,

            "elements": [
                "modularmachinery:blockcasing@0"
            ]
        },
        {
            "x": 7,
            "y": 7,
            "z": -1,

            "elements": [
                "modularmachinery:blockcasing@0"
            ]
        },
        {
            "x": 16,
            "y": -1,
            "z": 0,

            "elements": [
                "modularmachinery:blockcasing@0"
            ]
        },
        {
            "x": 13,
            "y": 12,
            "z": 4,

            "elements": [
                "modularmachinery:blockcasing@0"
            ]
        },
        {
            "x": 9,
            "y": 4,
            "z": -9,
            "elements": [
                "immersiveengineering:sheetmetal@9"
            ]
        },
        {
            "x": -4,
            "y": -2,
            "z": -9,
            "elements": [
                "contenttweaker:reinforced_mechine_casing@0"
            ]
        },
        {
            "x": 7,
            "y": 0,
            "z": -7,
            "elements": [
                "immersiveengineering:sheetmetal@9"
            ]
        },
        {
            "x": 11,
            "y": -1,
            "z": -9,
            "elements": [
                "ic2:fence@0"
            ]
        },
        {
            "x": -4,
            "y": -2,
            "z": -2,
            "elements": [
                "contenttweaker:reinforced_mechine_casing@0"
            ]
        },
        {
            "x": 13,
            "y": 11,
            "z": 4,

            "elements": [
                "modularmachinery:blockcasing@0"
            ]
        },
        {
            "x": 13,
            "y": 13,
            "z": 3,

            "elements": [
                "modularmachinery:blockcasing@0"
            ]
        },
        {
            "x": 16,
            "y": -2,
            "z": -5,
            "elements": [
                "contenttweaker:reinforced_mechine_casing@0"
            ]
        },
        {
            "x": 12,
            "y": -2,
            "z": 5,
            "elements": [
                "contenttweaker:reinforced_mechine_casing@0"
            ]
        },
        {
            "x": 16,
            "y": -2,
            "z": 0,
            "elements": [
                "contenttweaker:reinforced_mechine_casing@0"
            ]
        },
        {
            "x": 7,
            "y": 13,
            "z": 5,

            "elements": [
                "modularmachinery:blockcasing@0"
            ]
        },
        {
            "x": 13,
            "y": 12,
            "z": 3,

            "elements": [
                "modularmachinery:blockcasing@0"
            ]
        },
        {
            "x": 8,
            "y": 2,
            "z": 6,
            "elements": [
                "contenttweaker:reinforced_mechine_casing@0"
            ]
        },
        {
            "x": 9,
            "y": 3,
            "z": -9,
            "elements": [
                "immersiveengineering:sheetmetal@9"
            ]
        },
        {
            "x": 5,
            "y": 3,
            "z": -1,
            "elements": [
                "contenttweaker:reinforced_mechine_casing@0"
            ]
        },
        {
            "x": 12,
            "y": 13,
            "z": -3,

            "elements": [
                "modularmachinery:blockcasing@0"
            ]
        },
        {
            "x": 10,
            "y": 9,
            "z": 5,
            "elements": [
                "contenttweaker:reinforced_mechine_vents@0"
            ]
        },
        {
            "x": 13,
            "y": 7,
            "z": 3,

            "elements": [
                "modularmachinery:blockcasing@0"
            ]
        },
        {
            "x": 0,
            "y": -2,
            "z": -7,
            "elements": [
                "contenttweaker:reinforced_mechine_casing@0"
            ]
        },
        {
            "x": 13,
            "y": 11,
            "z": 3,

            "elements": [
                "modularmachinery:blockcasing@0"
            ]
        },
        {
            "x": 12,
            "y": 16,
            "z": -3,
            "elements": [
                "contenttweaker:reinforced_mechine_casing@0"
            ]
        },
        {
            "x": 0,
            "y": -2,
            "z": 8,
            "elements": [
                "contenttweaker:reinforced_mechine_casing@0"
            ]
        },
        {
            "x": 13,
            "y": 10,
            "z": 3,

            "elements": [
                "modularmachinery:blockcasing@0"
            ]
        },
        {
            "x": -1,
            "y": -2,
            "z": -2,
            "elements": [
                "contenttweaker:reinforced_mechine_casing@0"
            ]
        },
        {
            "x": 0,
            "y": 1,
            "z": 2,

            "elements": [
                "modularmachinery:blockcasing@0"
            ]
        },
        {
            "x": 10,
            "y": 10,
            "z": 5,
            "elements": [
                "contenttweaker:reinforced_mechine_vents@0"
            ]
        },
        {
            "x": 13,
            "y": 8,
            "z": 3,

            "elements": [
                "modularmachinery:blockcasing@0"
            ]
        },
        {
            "x": 1,
            "y": -2,
            "z": 6,
            "elements": [
                "contenttweaker:reinforced_mechine_casing@0"
            ]
        },
        {
            "x": 12,
            "y": 14,
            "z": -3,

            "elements": [
                "modularmachinery:blockcasing@0"
            ]
        },
        {
            "x": 15,
            "y": -2,
            "z": 5,
            "elements": [
                "contenttweaker:reinforced_mechine_casing@0"
            ]
        },
        {
            "x": 5,
            "y": 16,
            "z": 0,
            "elements": [
                "contenttweaker:reinforced_mechine_casing@0"
            ]
        },
        {
            "x": -1,
            "y": -2,
            "z": -9,
            "elements": [
                "contenttweaker:reinforced_mechine_casing@0"
            ]
        },
        {
            "x": -3,
            "y": -2,
            "z": -7,
            "elements": [
                "contenttweaker:reinforced_mechine_casing@0"
            ]
        },
        {
            "x": 5,
            "y": 5,
            "z": -1,
            "elements": [
                "contenttweaker:reinforced_mechine_casing@0"
            ]
        },
        {
            "x": 5,
            "y": 15,
            "z": 0,

            "elements": [
                "modularmachinery:blockcasing@0"
            ]
        },
        {
            "x": 13,
            "y": 4,
            "z": 5,

            "elements": [
                "modularmachinery:blockcasing@0"
            ]
        },
        {
            "x": 13,
            "y": 9,
            "z": 3,

            "elements": [
                "modularmachinery:blockcasing@0"
            ]
        },
        {
            "x": 10,
            "y": 7,
            "z": 5,
            "elements": [
                "contenttweaker:reinforced_mechine_vents@0"
            ]
        },
        {
            "x": 3,
            "y": -2,
            "z": -7,
            "elements": [
                "contenttweaker:reinforced_mechine_casing@0"
            ]
        },
        {
            "x": 0,
            "y": 3,
            "z": 2,
            "elements": [
                "contenttweaker:reinforced_mechine_casing@0"
            ]
        },
        {
            "x": 12,
            "y": 15,
            "z": -3,

            "elements": [
                "modularmachinery:blockcasing@0"
            ]
        },
        {
            "x": 14,
            "y": 8,
            "z": 0,

            "elements": [
                "modularmachinery:blockcasing@0"
            ]
        },
        {
            "x": 5,
            "y": 14,
            "z": 0,

            "elements": [
                "modularmachinery:blockcasing@0"
            ]
        },
        {
            "x": 13,
            "y": 5,
            "z": 5,

            "elements": [
                "modularmachinery:blockcasing@0"
            ]
        },
        {
            "x": -3,
            "y": 1,
            "z": 2,

            "elements": [
                "modularmachinery:blockcasing@0"
            ]
        },
        {
            "x": 15,
            "y": 13,
            "z": 1,

            "elements": [
                "modularmachinery:blockcasing@0"
            ]
        },
        {
            "x": 2,
            "y": -2,
            "z": -2,
            "elements": [
                "contenttweaker:reinforced_mechine_casing@0"
            ]
        },
        {
            "x": 15,
            "y": 15,
            "z": 1,

            "elements": [
                "modularmachinery:blockcasing@0"
            ]
        },
        {
            "x": 13,
            "y": 3,
            "z": 5,

            "elements": [
                "modularmachinery:blockcasing@0"
            ]
        },
        {
            "x": 4,
            "y": 4,
            "z": 1,
            "elements": [
                "contenttweaker:reinforced_mechine_vents@0"
            ]
        },
        {
            "x": 14,
            "y": 7,
            "z": 0,

            "elements": [
                "modularmachinery:blockcasing@0"
            ]
        },
        {
            "x": 10,
            "y": 8,
            "z": 5,
            "elements": [
                "contenttweaker:reinforced_mechine_vents@0"
            ]
        },
        {
            "x": 6,
            "y": -2,
            "z": 4,
            "elements": [
                "contenttweaker:reinforced_mechine_casing@0"
            ]
        },
        {
            "x": 5,
            "y": 13,
            "z": 0,

            "elements": [
                "modularmachinery:blockcasing@0"
            ]
        },
        {
            "x": 14,
            "y": 6,
            "z": 0,

            "elements": [
                "modularmachinery:blockcasing@0"
            ]
        },
        {
            "x": 12,
            "y": 4,
            "z": -9,
            "elements": [
                "immersiveengineering:sheetmetal@9"
            ]
        },
        {
            "x": -1,
            "y": 3,
            "z": 2,
            "elements": [
                "contenttweaker:reinforced_mechine_casing@0"
            ]
        },
        {
            "x": -2,
            "y": -2,
            "z": 8,
            "elements": [
                "contenttweaker:reinforced_mechine_casing@0"
            ]
        },
        {
            "x": 7,
            "y": 9,
            "z": 4,

            "elements": [
                "modularmachinery:blockcasing@0"
            ]
        },
        {
            "x": 10,
            "y": 15,
            "z": 6,

            "elements": [
                "modularmachinery:blockcasing@0"
            ]
        },
        {
            "x": 7,
            "y": 8,
            "z": 4,

            "elements": [
                "modularmachinery:blockcasing@0"
            ]
        },
        {
            "x": -2,
            "y": 1,
            "z": 2,

            "elements": [
                "modularmachinery:blockcasing@0"
            ]
        },
        {
            "x": 9,
            "y": -2,
            "z": 1,
            "elements": [
                "contenttweaker:reinforced_mechine_casing@0"
            ]
        },
        {
            "x": 13,
            "y": -2,
            "z": -5,
            "elements": [
                "contenttweaker:reinforced_mechine_casing@0"
            ]
        },
        {
            "x": 11,
            "y": 13,
            "z": 6,

            "elements": [
                "modularmachinery:blockcasing@0"
            ]
        },
        {
            "x": 1,
            "y": -2,
            "z": -2,
            "elements": [
                "contenttweaker:reinforced_mechine_casing@0"
            ]
        },
        {
            "x": 1,
            "y": 0,
            "z": 1,

            "elements": [
                "modularmachinery:blockcasing@0"
            ]
        },
        {
            "x": 9,
            "y": 2,
            "z": -7,
            "elements": [
                "immersiveengineering:sheetmetal@9"
            ]
        },
        {
            "x": 7,
            "y": 10,
            "z": 4,

            "elements": [
                "modularmachinery:blockcasing@0"
            ]
        },
        {
            "x": 0,
            "y": -1,
            "z": 2,

            "elements": [
                "modularmachinery:blockcasing@2"
            ]
        },
        {
            "x": 12,
            "y": 3,
            "z": -9,
            "elements": [
                "immersiveengineering:sheetmetal@9"
            ]
        },
        {
            "x": 10,
            "y": 13,
            "z": 5,

            "elements": [
                "modularmachinery:blockcasing@0"
            ]
        },
        {
            "x": 7,
            "y": 7,
            "z": 4,

            "elements": [
                "modularmachinery:blockcasing@0"
            ]
        },
        {
            "x": 13,
            "y": 8,
            "z": -1,

            "elements": [
                "modularmachinery:blockcasing@0"
            ]
        },
        {
            "x": 13,
            "y": 6,
            "z": 4,

            "elements": [
                "modularmachinery:blockcasing@0"
            ]
        },
        {
            "x": 15,
            "y": -1,
            "z": 4,

            "elements": [
                "modularmachinery:blockcasing@0"
            ]
        },
        {
            "x": 10,
            "y": 12,
            "z": 5,

            "elements": [
                "modularmachinery:blockcasing@0"
            ]
        },
        {
            "x": 12,
            "y": 5,
            "z": -9,
            "elements": [
                "immersiveengineering:sheetmetal@9"
            ]
        },
        {
            "x": 4,
            "y": 0,
            "z": 1,

            "elements": [
                "modularmachinery:blockcasing@0"
            ]
        },
        {
            "x": 9,
            "y": -2,
            "z": -7,
            "elements": [
                "contenttweaker:reinforced_mechine_casing@0"
            ]
        },
        {
            "x": 0,
            "y": -2,
            "z": -2,
            "elements": [
                "contenttweaker:reinforced_mechine_casing@0"
            ]
        },
        {
            "x": 13,
            "y": 12,
            "z": -1,

            "elements": [
                "modularmachinery:blockcasing@0"
            ]
        },
        {
            "x": 6,
            "y": -2,
            "z": 1,
            "elements": [
                "contenttweaker:reinforced_mechine_casing@0"
            ]
        },
        {
            "x": -1,
            "y": 1,
            "z": 2,

            "elements": [
                "modularmachinery:blockcasing@0"
            ]
        },
        {
            "x": 8,
            "y": -2,
            "z": -9,
            "elements": [
                "contenttweaker:reinforced_mechine_casing@0"
            ]
        },
        {
            "x": -1,
            "y": -1,
            "z": 2,

            "elements": [
                "modularmachinery:blockcasing@2"
            ]
        },
        {
            "x": 10,
            "y": 11,
            "z": 5,
            "elements": [
                "contenttweaker:reinforced_mechine_vents@0"
            ]
        },
        {
            "x": 9,
            "y": 4,
            "z": -7,
            "elements": [
                "immersiveengineering:sheetmetal@9"
            ]
        },
        {
            "x": 3,
            "y": -2,
            "z": 1,
            "elements": [
                "contenttweaker:reinforced_mechine_casing@0"
            ]
        },
        {
            "x": 4,
            "y": -1,
            "z": -1,
            "elements": [
                "contenttweaker:reinforced_mechine_casing@0"
            ]
        },
        {
            "x": 7,
            "y": 16,
            "z": 5,
            "elements": [
                "contenttweaker:reinforced_mechine_casing@0"
            ]
        },
        {
            "x": 1,
            "y": 3,
            "z": 2,
            "elements": [
                "contenttweaker:reinforced_mechine_casing@0"
            ]
        },
        {
            "x": 13,
            "y": 10,
            "z": -1,

            "elements": [
                "modularmachinery:blockcasing@0"
            ]
        },
        {
            "x": 12,
            "y": -2,
            "z": -7,
            "elements": [
                "contenttweaker:reinforced_mechine_casing@0"
            ]
        },
        {
            "x": 12,
            "y": 0,
            "z": -9,
            "elements": [
                "immersiveengineering:sheetmetal@9"
            ]
        },
        {
            "x": -4,
            "y": -2,
            "z": 8,
            "elements": [
                "contenttweaker:reinforced_mechine_casing@0"
            ]
        },
        {
            "x": 13,
            "y": 9,
            "z": 4,

            "elements": [
                "modularmachinery:blockcasing@0"
            ]
        },
        {
            "x": 9,
            "y": 2,
            "z": -9,
            "elements": [
                "immersiveengineering:sheetmetal@9"
            ]
        },
        {
            "x": 7,
            "y": 9,
            "z": -1,

            "elements": [
                "modularmachinery:blockcasing@0"
            ]
        },
        {
            "x": -2,
            "y": -1,
            "z": 2,

            "elements": [
                "modularmachinery:blockcasing@2"
            ]
        },
        {
            "x": 3,
            "y": -2,
            "z": -2,
            "elements": [
                "contenttweaker:reinforced_mechine_casing@0"
            ]
        },
        {
            "x": 1,
            "y": 4,
            "z": 1,
            "elements": [
                "contenttweaker:reinforced_mechine_vents@0"
            ]
        },
        {
            "x": 7,
            "y": 15,
            "z": 5,

            "elements": [
                "modularmachinery:blockcasing@0"
            ]
        },
        {
            "x": 11,
            "y": -2,
            "z": -9,
            "elements": [
                "contenttweaker:reinforced_mechine_casing@0"
            ]
        },
        {
            "x": 9,
            "y": 0,
            "z": -9,
            "elements": [
                "immersiveengineering:sheetmetal@9"
            ]
        },
        {
            "x": 7,
            "y": 2,
            "z": -7,
            "elements": [
                "immersiveengineering:sheetmetal@9"
            ]
        },
        {
            "x": 13,
            "y": -2,
            "z": 0,
            "elements": [
                "contenttweaker:reinforced_mechine_casing@0"
            ]
        },
        {
            "x": 9,
            "y": 1,
            "z": -9,
            "elements": [
                "immersiveengineering:sheetmetal@9"
            ]
        },
        {
            "x": 13,
            "y": 10,
            "z": 4,

            "elements": [
                "modularmachinery:blockcasing@0"
            ]
        },
        {
            "x": 11,
            "y": 15,
            "z": 6,

            "elements": [
                "modularmachinery:blockcasing@0"
            ]
        },
        {
            "x": 7,
            "y": 6,
            "z": 4,

            "elements": [
                "modularmachinery:blockcasing@0"
            ]
        },
        {
            "x": 4,
            "y": -2,
            "z": 6,
            "elements": [
                "contenttweaker:reinforced_mechine_casing@0"
            ]
        },
        {
            "x": 13,
            "y": 14,
            "z": 5,

            "elements": [
                "modularmachinery:blockcasing@0"
            ]
        },
        {
            "x": 13,
            "y": 7,
            "z": 4,

            "elements": [
                "modularmachinery:blockcasing@0"
            ]
        },
        {
            "x": 1,
            "y": 1,
            "z": 2,

            "elements": [
                "modularmachinery:blockcasing@0"
            ]
        },
        {
            "x": 12,
            "y": -2,
            "z": 1,
            "elements": [
                "contenttweaker:reinforced_mechine_casing@0"
            ]
        },
        {
            "x": 17,
            "y": -2,
            "z": -9,
            "elements": [
                "contenttweaker:reinforced_mechine_casing@0"
            ]
        },
        {
            "x": -2,
            "y": -2,
            "z": -2,
            "elements": [
                "contenttweaker:reinforced_mechine_casing@0"
            ]
        },
        {
            "x": -3,
            "y": -2,
            "z": 8,
            "elements": [
                "contenttweaker:reinforced_mechine_casing@0"
            ]
        },
        {
            "x": 1,
            "y": -1,
            "z": 2,

            "elements": [
                "modularmachinery:blockcasing@2"
            ]
        },
        {
            "x": 12,
            "y": 2,
            "z": -9,
            "elements": [
                "immersiveengineering:sheetmetal@9"
            ]
        },
        {
            "x": 13,
            "y": 8,
            "z": 4,

            "elements": [
                "modularmachinery:blockcasing@0"
            ]
        },
        {
            "x": 13,
            "y": 13,
            "z": 5,

            "elements": [
                "modularmachinery:blockcasing@0"
            ]
        },
        {
            "x": 13,
            "y": 0,
            "z": -7,
            "elements": [
                "immersiveengineering:sheetmetal@9"
            ]
        },
        {
            "x": 14,
            "y": -2,
            "z": -9,
            "elements": [
                "contenttweaker:reinforced_mechine_casing@0"
            ]
        },
        {
            "x": 10,
            "y": -2,
            "z": 0,
            "elements": [
                "contenttweaker:reinforced_mechine_casing@0"
            ]
        },
        {
            "x": 12,
            "y": 1,
            "z": -9,
            "elements": [
                "immersiveengineering:sheetmetal@9"
            ]
        },
        {
            "x": 7,
            "y": 4,
            "z": -7,
            "elements": [
                "immersiveengineering:sheetmetal@9"
            ]
        },
        {
            "x": 15,
            "y": 4,
            "z": 2,

            "elements": [
                "modularmachinery:blockcasing@0"
            ]
        },
        {
            "x": 5,
            "y": 5,
            "z": 0,

            "elements": [
                "modularmachinery:blockcasing@0"
            ]
        },
        {
            "x": -3,
            "y": 0,
            "z": 1,
            "elements": [
                "contenttweaker:reinforced_mechine_vents@0"
            ]
        },
        {
            "x": -2,
            "y": -2,
            "z": -7,
            "elements": [
                "contenttweaker:reinforced_mechine_casing@0"
            ]
        },
        {
            "x": -3,
            "y": -2,
            "z": 1,
            "elements": [
                "contenttweaker:reinforced_mechine_casing@0"
            ]
        },
        {
            "x": 0,
            "y": 2,
            "z": 1,
            "elements": [
                "contenttweaker:reinforced_mechine_vents@0"
            ]
        },
        {
            "x": 6,
            "y": 11,
            "z": 2,

            "elements": [
                "modularmachinery:blockcasing@0"
            ]
        },
        {
            "x": 13,
            "y": 1,
            "z": -8,
            "elements": [
                "immersiveengineering:sheetmetal@9"
            ]
        },
        {
            "x": 14,
            "y": -2,
            "z": -3,
            "elements": [
                "contenttweaker:reinforced_mechine_casing@0"
            ]
        },
        {
            "x": 10,
            "y": -2,
            "z": -5,
            "elements": [
                "contenttweaker:reinforced_mechine_casing@0"
            ]
        },
        {
            "x": 7,
            "y": 5,
            "z": -8,
            "elements": [
                "immersiveengineering:sheetmetal@9"
            ]
        },
        {
            "x": -1,
            "y": -2,
            "z": 6,
            "elements": [
                "contenttweaker:reinforced_mechine_casing@0"
            ]
        },
        {
            "x": 11,
            "y": 5,
            "z": -4,

            "elements": [
                "modularmachinery:blockcasing@0"
            ]
        },
        {
            "x": -1,
            "y": 4,
            "z": 1,
            "elements": [
                "contenttweaker:reinforced_mechine_casing@0"
            ]
        },
        {
            "x": 13,
            "y": -2,
            "z": -2,
            "elements": [
                "contenttweaker:reinforced_mechine_casing@0"
            ]
        },
        {
            "x": 14,
            "y": -2,
            "z": -4,
            "elements": [
                "contenttweaker:reinforced_mechine_casing@0"
            ]
        },
        {
            "x": 5,
            "y": -2,
            "z": -7,
            "elements": [
                "contenttweaker:reinforced_mechine_casing@0"
            ]
        },
        {
            "x": 2,
            "y": -2,
            "z": 1,
            "elements": [
                "contenttweaker:reinforced_mechine_casing@0"
            ]
        },
        {
            "x": 12,
            "y": 4,
            "z": -3,

            "elements": [
                "modularmachinery:blockcasing@0"
            ]
        },
        {
            "x": 2,
            "y": -2,
            "z": 6,
            "elements": [
                "contenttweaker:reinforced_mechine_casing@0"
            ]
        },
        {
            "x": 14,
            "y": -1,
            "z": -3,

            "elements": [
                "modularmachinery:blockcasing@0"
            ]
        },
        {
            "x": 8,
            "y": 6,
            "z": -2,

            "elements": [
                "modularmachinery:blockcasing@0"
            ]
        },
        {
            "x": 12,
            "y": -2,
            "z": 3,
            "elements": [
                "contenttweaker:reinforced_mechine_casing@0"
            ]
        },
        {
            "x": 6,
            "y": 9,
            "z": 2,

            "elements": [
                "modularmachinery:blockcasing@0"
            ]
        },
        {
            "x": 11,
            "y": -2,
            "z": -3,
            "elements": [
                "contenttweaker:reinforced_mechine_casing@0"
            ]
        },
        {
            "x": 7,
            "y": 3,
            "z": -8,
            "elements": [
                "immersiveengineering:sheetmetal@9"
            ]
        },
        {
            "x": 4,
            "y": -2,
            "z": -2,
            "elements": [
                "contenttweaker:reinforced_mechine_casing@0"
            ]
        },
        {
            "x": 12,
            "y": -2,
            "z": 4,
            "elements": [
                "contenttweaker:reinforced_mechine_casing@0"
            ]
        },
        {
            "x": 9,
            "y": -2,
            "z": 3,
            "elements": [
                "contenttweaker:reinforced_mechine_casing@0"
            ]
        },
        {
            "x": 9,
            "y": 16,
            "z": -4,
            "elements": [
                "contenttweaker:reinforced_mechine_casing@0"
            ]
        },
        {
            "x": 8,
            "y": 14,
            "z": -4,
            "elements": [
                "contenttweaker:reinforced_mechine_casing@0"
            ]
        },
        {
            "x": -1,
            "y": -2,
            "z": 1,
            "elements": [
                "contenttweaker:reinforced_mechine_casing@0"
            ]
        },
        {
            "x": 12,
            "y": 3,
            "z": -3,

            "elements": [
                "modularmachinery:blockcasing@0"
            ]
        },
        {
            "x": 7,
            "y": 1,
            "z": -8,
            "elements": [
                "immersiveengineering:sheetmetal@9"
            ]
        },
        {
            "x": 8,
            "y": 13,
            "z": -4,
            "elements": [
                "contenttweaker:reinforced_mechine_casing@0"
            ]
        },
        {
            "x": 7,
            "y": 13,
            "z": 4,

            "elements": [
                "modularmachinery:blockcasing@0"
            ]
        },
        {
            "x": 8,
            "y": -2,
            "z": -7,
            "elements": [
                "contenttweaker:reinforced_mechine_casing@0"
            ]
        },
        {
            "x": 11,
            "y": 0,
            "z": -5,

            "elements": [
                "modularmachinery:blockcasing@0"
            ]
        },
        {
            "x": 9,
            "y": 8,
            "z": -3,

            "elements": [
                "modularmachinery:blockcasing@0"
            ]
        },
        {
            "x": 9,
            "y": 7,
            "z": -3,

            "elements": [
                "modularmachinery:blockcasing@0"
            ]
        },
        {
            "x": 9,
            "y": 15,
            "z": -4,

            "elements": [
                "modularmachinery:blockcasing@0"
            ]
        },
        {
            "x": 7,
            "y": -2,
            "z": -2,
            "elements": [
                "contenttweaker:reinforced_mechine_casing@0"
            ]
        },
        {
            "x": 15,
            "y": -2,
            "z": 4,
            "elements": [
                "contenttweaker:reinforced_mechine_casing@0"
            ]
        },
        {
            "x": 5,
            "y": 0,
            "z": -2,

            "elements": [
                "modularmachinery:blockcasing@0"
            ]
        },
        {
            "x": 16,
            "y": -2,
            "z": -4,
            "elements": [
                "contenttweaker:reinforced_mechine_casing@0"
            ]
        },
        {
            "x": 13,
            "y": 5,
            "z": -8,
            "elements": [
                "immersiveengineering:sheetmetal@9"
            ]
        },
        {
            "x": 11,
            "y": -2,
            "z": -10,
            "elements": [
                "contenttweaker:reinforced_mechine_casing@0"
            ]
        },
        {
            "x": 10,
            "y": 7,
            "z": -8,
            "elements": [
                "contenttweaker:reinforced_mechine_casing@0"
            ]
        },
        {
            "x": 8,
            "y": 16,
            "z": -4,
            "elements": [
                "contenttweaker:reinforced_mechine_casing@0"
            ]
        },
        {
            "x": 6,
            "y": 13,
            "z": 2,

            "elements": [
                "modularmachinery:blockcasing@0"
            ]
        },
        {
            "x": 12,
            "y": 1,
            "z": -3,

            "elements": [
                "modularmachinery:blockcasing@0"
            ]
        },
        {
            "x": 0,
            "y": -2,
            "z": 1,
            "elements": [
                "contenttweaker:reinforced_mechine_casing@0"
            ]
        },
        {
            "x": 9,
            "y": 14,
            "z": -4,

            "elements": [
                "modularmachinery:blockcasing@0"
            ]
        },
        {
            "x": 9,
            "y": 6,
            "z": -3,

            "elements": [
                "modularmachinery:blockcasing@0"
            ]
        },
        {
            "x": -1,
            "y": 2,
            "z": 1,
            "elements": [
                "contenttweaker:reinforced_mechine_vents@0"
            ]
        },
        {
            "x": 9,
            "y": 0,
            "z": -7,
            "elements": [
                "immersiveengineering:sheetmetal@9"
            ]
        },
        {
            "x": 9,
            "y": 13,
            "z": -4,

            "elements": [
                "modularmachinery:blockcasing@0"
            ]
        },
        {
            "x": 7,
            "y": 11,
            "z": 4,

            "elements": [
                "modularmachinery:blockcasing@0"
            ]
        },
        {
            "x": 8,
            "y": 0,
            "z": -5,
            "elements": [
                "contenttweaker:reinforced_mechine_casing@0"
            ]
        },
        {
            "x": -3,
            "y": -1,
            "z": 2,

            "elements": [
                "modularmachinery:blockcasing@2"
            ]
        },
        {
            "x": 13,
            "y": 3,
            "z": -8,
            "elements": [
                "immersiveengineering:sheetmetal@9"
            ]
        },
        {
            "x": 8,
            "y": 15,
            "z": -4,
            "elements": [
                "contenttweaker:reinforced_mechine_casing@0"
            ]
        },
        {
            "x": 7,
            "y": -2,
            "z": -5,
            "elements": [
                "contenttweaker:reinforced_mechine_casing@0"
            ]
        },
        {
            "x": 10,
            "y": -2,
            "z": -2,
            "elements": [
                "contenttweaker:reinforced_mechine_casing@0"
            ]
        },
        {
            "x": 7,
            "y": 12,
            "z": 4,

            "elements": [
                "modularmachinery:blockcasing@0"
            ]
        },
        {
            "x": 7,
            "y": 6,
            "z": 3,

            "elements": [
                "modularmachinery:blockcasing@0"
            ]
        },
        {
            "x": 10,
            "y": -1,
            "z": -5,

            "elements": [
                "modularmachinery:blockcasing@0"
            ]
        },
        {
            "x": 12,
            "y": 2,
            "z": -3,

            "elements": [
                "modularmachinery:blockcasing@0"
            ]
        },
        {
            "x": 17,
            "y": -2,
            "z": -4,
            "elements": [
                "contenttweaker:reinforced_mechine_casing@0"
            ]
        },
        {
            "x": 14,
            "y": -2,
            "z": -10,
            "elements": [
                "contenttweaker:reinforced_mechine_casing@0"
            ]
        },
        {
            "x": 2,
            "y": -2,
            "z": -7,
            "elements": [
                "contenttweaker:reinforced_mechine_casing@0"
            ]
        },
        {
            "x": 1,
            "y": -2,
            "z": 1,
            "elements": [
                "contenttweaker:reinforced_mechine_casing@0"
            ]
        },
        {
            "x": 9,
            "y": 11,
            "z": -3,

            "elements": [
                "modularmachinery:blockcasing@0"
            ]
        },
        {
            "x": 14,
            "y": 10,
            "z": 0,

            "elements": [
                "modularmachinery:blockcasing@0"
            ]
        },
        {
            "x": 7,
            "y": 7,
            "z": 3,

            "elements": [
                "modularmachinery:blockcasing@0"
            ]
        },
        {
            "x": 9,
            "y": -2,
            "z": 5,
            "elements": [
                "contenttweaker:reinforced_mechine_casing@0"
            ]
        },
        {
            "x": 15,
            "y": 14,
            "z": 2,

            "elements": [
                "modularmachinery:blockcasing@0"
            ]
        },
        {
            "x": 1,
            "y": -2,
            "z": 8,
            "elements": [
                "contenttweaker:reinforced_mechine_casing@0"
            ]
        },
        {
            "x": 17,
            "y": -2,
            "z": -10,
            "elements": [
                "contenttweaker:reinforced_mechine_casing@0"
            ]
        },
        {
            "x": 7,
            "y": 5,
            "z": 5,

            "elements": [
                "modularmachinery:blockcasing@0"
            ]
        },
        {
            "x": 9,
            "y": 12,
            "z": -3,

            "elements": [
                "modularmachinery:blockcasing@0"
            ]
        },
        {
            "x": 3,
            "y": 4,
            "z": 1,
            "elements": [
                "contenttweaker:reinforced_mechine_vents@0"
            ]
        },
        {
            "x": 14,
            "y": 9,
            "z": 0,

            "elements": [
                "modularmachinery:blockcasing@0"
            ]
        },
        {
            "x": 10,
            "y": -2,
            "z": -4,
            "elements": [
                "contenttweaker:reinforced_mechine_casing@0"
            ]
        },
        {
            "x": 12,
            "y": 10,
            "z": -3,
            "elements": [
                "contenttweaker:reinforced_mechine_casing@0"
            ]
        },
        {
            "x": 7,
            "y": 8,
            "z": 3,

            "elements": [
                "modularmachinery:blockcasing@0"
            ]
        },
        {
            "x": 12,
            "y": 9,
            "z": -3,
            "elements": [
                "contenttweaker:reinforced_mechine_casing@0"
            ]
        },
        {
            "x": -2,
            "y": -2,
            "z": -5,
            "elements": [
                "contenttweaker:reinforced_mechine_casing@0"
            ]
        },
        {
            "x": 7,
            "y": 4,
            "z": 5,

            "elements": [
                "modularmachinery:blockcasing@0"
            ]
        },
        {
            "x": 0,
            "y": -2,
            "z": 5,
            "elements": [
                "contenttweaker:reinforced_mechine_casing@0"
            ]
        },
        {
            "x": 12,
            "y": 11,
            "z": -3,
            "elements": [
                "contenttweaker:reinforced_mechine_casing@0"
            ]
        },
        {
            "x": 7,
            "y": 9,
            "z": 3,

            "elements": [
                "modularmachinery:blockcasing@0"
            ]
        },
        {
            "x": 16,
            "y": 0,
            "z": 3,
            "elements": [
                "contenttweaker:reinforced_mechine_casing@0"
            ]
        },
        {
            "x": 1,
            "y": -2,
            "z": -7,
            "elements": [
                "contenttweaker:reinforced_mechine_casing@0"
            ]
        },
        {
            "x": -2,
            "y": -2,
            "z": 1,
            "elements": [
                "contenttweaker:reinforced_mechine_casing@0"
            ]
        },
        {
            "x": 9,
            "y": 10,
            "z": -3,

            "elements": [
                "modularmachinery:blockcasing@0"
            ]
        },
        {
            "x": 14,
            "y": 12,
            "z": 0,

            "elements": [
                "modularmachinery:blockcasing@0"
            ]
        },
        {
            "x": -2,
            "y": -2,
            "z": 6,
            "elements": [
                "contenttweaker:reinforced_mechine_casing@0"
            ]
        },
        {
            "x": 12,
            "y": 12,
            "z": -3,
            "elements": [
                "contenttweaker:reinforced_mechine_casing@0"
            ]
        },
        {
            "x": 7,
            "y": 3,
            "z": 5,

            "elements": [
                "modularmachinery:blockcasing@0"
            ]
        },
        {
            "x": 7,
            "y": 10,
            "z": 3,

            "elements": [
                "modularmachinery:blockcasing@0"
            ]
        },
        {
            "x": 15,
            "y": 16,
            "z": -1,
            "elements": [
                "contenttweaker:reinforced_mechine_casing@0"
            ]
        },
        {
            "x": 6,
            "y": -2,
            "z": 8,
            "elements": [
                "contenttweaker:reinforced_mechine_casing@0"
            ]
        },
        {
            "x": 13,
            "y": 6,
            "z": 3,

            "elements": [
                "modularmachinery:blockcasing@0"
            ]
        },
        {
            "x": 15,
            "y": -1,
            "z": 3,

            "elements": [
                "modularmachinery:blockcasing@0"
            ]
        },
        {
            "x": 12,
            "y": 5,
            "z": -4,
            "elements": [
                "contenttweaker:reinforced_mechine_casing@0"
            ]
        },
        {
            "x": 9,
            "y": 9,
            "z": -3,

            "elements": [
                "modularmachinery:blockcasing@0"
            ]
        },
        {
            "x": 7,
            "y": 11,
            "z": 3,

            "elements": [
                "modularmachinery:blockcasing@0"
            ]
        },
        {
            "x": 12,
            "y": 14,
            "z": -4,
            "elements": [
                "contenttweaker:reinforced_mechine_casing@0"
            ]
        },
        {
            "x": 14,
            "y": 11,
            "z": 0,

            "elements": [
                "modularmachinery:blockcasing@0"
            ]
        },
        {
            "x": 4,
            "y": -2,
            "z": -7,
            "elements": [
                "contenttweaker:reinforced_mechine_casing@0"
            ]
        },
        {
            "x": 11,
            "y": 2,
            "z": -4,

            "elements": [
                "modularmachinery:blockcasing@0"
            ]
        },
        {
            "x": 12,
            "y": 6,
            "z": -3,
            "elements": [
                "contenttweaker:reinforced_mechine_casing@0"
            ]
        },
        {
            "x": 7,
            "y": 1,
            "z": 5,

            "elements": [
                "modularmachinery:blockcasing@0"
            ]
        },
        {
            "x": 12,
            "y": 4,
            "z": -4,
            "elements": [
                "contenttweaker:reinforced_mechine_casing@0"
            ]
        },
        {
            "x": 14,
            "y": 13,
            "z": 0,

            "elements": [
                "modularmachinery:blockcasing@0"
            ]
        },
        {
            "x": 15,
            "y": -2,
            "z": 3,
            "elements": [
                "contenttweaker:reinforced_mechine_casing@0"
            ]
        },
        {
            "x": 7,
            "y": 2,
            "z": 5,

            "elements": [
                "modularmachinery:blockcasing@0"
            ]
        },
        {
            "x": 3,
            "y": -2,
            "z": 5,
            "elements": [
                "contenttweaker:reinforced_mechine_casing@0"
            ]
        },
        {
            "x": 13,
            "y": -1,
            "z": -4,

