{
    "registryname":"mana_infusion",
    "localizedname":"魔力灌注机",
    "color": "AFEEEE",
    "parts": [
        {
            "x": 0,
            "y": 0,
            "z": 0,
            "elements": [
                "modularmachinery:mana_infusion_controller@2"
            ]
        },
        {
            "x": 1,
            "y": 3,
            "z": 4,
            "elements": [
                "botania:managlasspane@0"
            ]
        },
        {
            "x": 2,
            "y": 6,
            "z": 8,
            "elements": [
                "botania:quartzstairsmana@1"
            ]
        },
        {
            "x": 2,
            "y": 2,
            "z": 6,
            "elements": [
                "botania:pylon@1"
            ]
        },
        {
            "x": 0,
            "y": 11,
            "z": 4,
            "elements": [
                "botania:managlasspane@0"
            ]
        },
        {
            "x": -3,
            "y": 0,
            "z": 5,
            "elements": [
                "botania:quartztypemana@0"
            ]
        },
        {
            "x": -3,
            "y": 6,
            "z": 7,
            "elements": [
                "botania:quartzstairsmana@0"
            ]
        },
        {
            "x": 0,
            "y": 10,
            "z": 4,
            "elements": [
                "botania:managlasspane@0"
            ]
        },
        {
            "x": -5,
            "y": 6,
            "z": 5,
            "elements": [
                "botania:quartzstairsmana@0"
            ]
        },
        {
            "x": 2,
            "y": 6,
            "z": -1,
            "elements": [
                "botania:quartzstairsmana@1"
            ]
        },
        {
            "x": 0,
            "y": 9,
            "z": 3,
            "elements": [
                "botania:quartzstairsmana@2"
            ]
        },
        {
            "x": -1,
            "y": 7,
            "z": 6,
            "elements": [
                "botania:quartzstairsmana@0"
            ]
        },
        {
            "x": -3,
            "y": 6,
            "z": 0,
            "elements": [
                "botania:quartzstairsmana@2"
            ]
        },
        {
            "x": 0,
            "y": 12,
            "z": 4,
            "elements": [
                "botania:managlass@0"
            ]
        },
        {
            "x": 1,
            "y": 4,
            "z": 4,
            "elements": [
                "botania:managlasspane@0"
            ]
        },
        {
            "x": 0,
            "y": 6,
            "z": 9,
            "elements": [
                "botania:quartzstairsmana@3"
            ]
        },
        {
            "x": -4,
            "y": 0,
            "z": 3,
            "elements": [
                "botania:quartzstairsmana@0"
            ]
        },
        {
            "x": -3,
            "y": 5,
            "z": 0,
            "elements": [
                "botania:quartzstairsmana@4"
            ]
        },
        {
            "x": 0,
            "y": 7,
            "z": 2,
            "elements": [
                "botania:quartztypemana@1"
            ]
        },
        {
            "x": 3,
            "y": 7,
            "z": 4,
            "elements": [
                "botania:quartzslabmanahalf@0"
            ]
        },
        {
            "x": 0,
            "y": 9,
            "z": 4,
            "elements": [
                "botania:managlasspane@0"
            ]
        },
        {
            "x": 2,
            "y": 6,
            "z": 1,
            "elements": [
                "botania:quartzslabmanahalf@0"
            ]
        },
        {
            "x": 1,
            "y": 0,
            "z": 0,
            "elements": [
                "botania:quartzstairsmana@2"
            ]
        },
        {
            "x": 0,
            "y": 13,
            "z": 4,
            "elements": [
                "botania:quartzslabmanahalf@0"
            ]
        },
        {
            "x": -1,
            "y": 6,
            "z": 8,
            "elements": [
                "botania:quartzslabmanahalf@0"
            ]
        },
        {
            "x": -4,
            "y": 6,
            "z": 7,
            "elements": [
                "botania:quartzstairsmana@3"
            ]
        },
        {
            "x": -2,
            "y": 0,
            "z": 5,
            "elements": [
                "botania:quartztypemana@0"
            ]
        },
        {
            "x": -4,
            "y": 6,
            "z": 5,
            "elements": [
                "botania:quartzslabmanahalf@0"
            ]
        },
        {
            "x": 5,
            "y": 5,
            "z": 6,
            "elements": [
                "botania:quartzslabmanahalf@8"
            ]
        },
        {
            "x": 0,
            "y": 8,
            "z": 4,
            "elements": [
                "botania:quartztypemana@2"
            ]
        },
        {
            "x": 0,
            "y": 7,
            "z": 4,
            "elements": [
                "botania:quartztypemana@2"
            ]
        },
        {
            "x": -2,
            "y": 0,
            "z": 8,
            "elements": [
                "botania:quartzstairsmana@3"
            ]
        },
        {
            "x": 0,
            "y": 7,
            "z": 3,
            "elements": [
                "botania:quartztypemana@1"
            ]
        },
        {
            "x": 2,
            "y": 0,
            "z": 7,
            "elements": [
                "botania:quartztypemana@0"
            ]
        },
        {
            "x": 1,
            "y": 6,
            "z": 9,
            "elements": [
                "botania:quartzstairsmana@3"
            ]
        },
        {
            "x": 2,
            "y": 6,
            "z": 6,
            "elements": [
                "botania:quartzslabmanahalf@8"
            ]
        },
        {
            "x": -4,
            "y": 5,
            "z": 0,
            "elements": [
                "botania:quartzslabmanahalf@8"
            ]
        },
        {
            "x": 1,
            "y": 5,
            "z": 4,
            "elements": [
                "botania:managlasspane@0"
            ]
        },
        {
            "x": 2,
            "y": 5,
            "z": -1,
            "elements": [
                "botania:quartzslabmanahalf@8"
            ]
        },
        {
            "x": 3,
            "y": 0,
            "z": 2,
            "elements": [
                "botania:quartztypemana@0"
            ]
        },
        {
            "x": 4,
            "y": 0,
            "z": 4,
            "elements": [
                "botania:quartztypemana@1"
            ]
        },
        {
            "x": 0,
            "y": 8,
            "z": 3,
            "elements": [
                "botania:quartztypemana@1"
            ]
        },
        {
            "x": 3,
            "y": 6,
            "z": 7,
            "elements": [
                "botania:quartzstairsmana@1"
            ]
        },
        {
            "x": 2,
            "y": 0,
            "z": 0,
            "elements": [
                "botania:quartzstairsmana@2"
            ]
        },
        {
            "x": -3,
            "y": 6,
            "z": 5,
            "elements": [
                "botania:quartzslabmanahalf@8"
            ]
        },
        {
            "x": 2,
            "y": 5,
            "z": 9,
            "elements": [
                "botania:quartzslabmanahalf@8"
            ]
        },
        {
            "x": -4,
            "y": 5,
            "z": 8,
            "elements": [
                "botania:quartzslabmanahalf@8"
            ]
        },
        {
            "x": -4,
            "y": 4,
            "z": 7,
            "elements": [
                "botania:quartztypemana@2"
            ]
        },
        {
            "x": 1,
            "y": 0,
            "z": 6,
            "elements": [
                "botania:quartztypemana@0"
            ]
        },
        {
            "x": 1,
            "y": 8,
            "z": 4,
            "elements": [
                "botania:quartztypemana@1"
            ]
        },
        {
            "x": 4,
            "y": 6,
            "z": 4,
            "elements": [
                "botania:quartzslabmanafull@0"
            ]
        },
        {
            "x": 5,
            "y": 5,
            "z": 1,
            "elements": [
                "botania:quartzstairsmana@5"
            ]
        },
        {
            "x": -1,
            "y": 0,
            "z": 7,
            "elements": [
                "botania:quartztypemana@0"
            ]
        },
        {
            "x": 5,
            "y": 6,
            "z": 6,
            "elements": [
                "botania:quartzstairsmana@3"
            ]
        },
        {
            "x": 1,
            "y": 7,
            "z": 4,
            "elements": [
                "botania:quartztypemana@1"
            ]
        },
        {
            "x": 1,
            "y": 0,
            "z": 8,
            "elements": [
                "botania:quartzstairsmana@3"
            ]
        },
        {
            "x": 2,
            "y": 0,
            "z": 3,
            "elements": [
                "botania:quartztypemana@0"
            ]
        },
        {
            "x": 4,
            "y": 6,
            "z": 1,
            "elements": [
                "botania:quartzstairsmana@1"
            ]
        },
        {
            "x": 0,
            "y": 5,
            "z": 3,
            "elements": [
                "botania:managlasspane@0"
            ]
        },
        {
            "x": 2,
            "y": 6,
            "z": 9,
            "elements": [
                "botania:quartzstairsmana@1"
            ]
        },
        {
            "x": -4,
            "y": 5,
            "z": 7,
            "elements": [
                "botania:quartzstairsmana@4"
            ]
        },
        {
            "x": 0,
            "y": 0,
            "z": 2,
            "elements": [
                "botania:quartztypemana@1"
            ]
        },
        {
            "x": -1,
            "y": 0,
            "z": 0,
            "elements": [
                "botania:quartzstairsmana@2"
            ]
        },
        {
            "x": -4,
            "y": 1,
            "z": 7,
            "elements": [
                "botania:quartztypemana@2"
            ]
        },
        {
            "x": -3,
            "y": 0,
            "z": 2,
            "elements": [
                "botania:quartztypemana@0"
            ]
        },
        {
            "x": 0,
            "y": 0,
            "z": 5,
            "elements": [
                "modularmachinery:blockmanaproviderinput@0",
                "gugu-utils:sparkmanahatch"
            ]
        },
        {
            "x": 0,
            "y": 4,
            "z": 3,
            "elements": [
                "botania:managlasspane@0"
            ]
        },
        {
            "x": 2,
            "y": 0,
            "z": 6,
            "elements": [
                "botania:quartztypemana@0"
            ]
        },
        {
            "x": 3,
            "y": 6,
            "z": 4,
            "elements": [
                "botania:quartzslabmanahalf@8"
            ]
        },
        {
            "x": 4,
            "y": 5,
            "z": 1,
            "elements": [
                "botania:quartzstairsmana@6"
            ]
        },
        {
            "x": -2,
            "y": 6,
            "z": 0,
            "elements": [
                "botania:quartzstairsmana@0"
            ]
        },
        {
            "x": 2,
            "y": 8,
            "z": 4,
            "elements": [
                "botania:quartzslabmanahalf@0"
            ]
        },
        {
            "x": 3,
            "y": 0,
            "z": 3,
            "elements": [
                "botania:quartztypemana@0"
            ]
        },
        {
            "x": 4,
            "y": 4,
            "z": 1,
            "elements": [
                "botania:quartztypemana@2"
            ]
        },
        {
            "x": 2,
            "y": 7,
            "z": 4,
            "elements": [
                "botania:quartztypemana@1"
            ]
        },
        {
            "x": -1,
            "y": 6,
            "z": 9,
            "elements": [
                "botania:quartzstairsmana@3"
            ]
        },
        {
            "x": -4,
            "y": 3,
            "z": 7,
            "elements": [
                "botania:quartztypemana@2"
            ]
        },
        {
            "x": 1,
            "y": 9,
            "z": 4,
            "elements": [
                "botania:quartzstairsmana@1"
            ]
        },
        {
            "x": -4,
            "y": 6,
            "z": 6,
            "elements": [
                "botania:quartzstairsmana@0"
            ]
        },
        {
            "x": 1,
            "y": 6,
            "z": 7,
            "elements": [
                "botania:quartzslabmanahalf@8"
            ]
        },
        {
            "x": -4,
            "y": 0,
            "z": 7,
            "elements": [
                "botania:quartztypemana@2"
            ]
        },
        {
            "x": 2,
            "y": 1,
            "z": 6,
            "elements": [
                "botania:managlasspane@0"
            ]
        },
        {
            "x": 0,
            "y": 3,
            "z": 3,
            "elements": [
                "botania:managlasspane@0"
            ]
        },
        {
            "x": -1,
            "y": 8,
            "z": 3,
            "elements": [
                "botania:quartzslabmanahalf@0"
            ]
        },
        {
            "x": 4,
            "y": 3,
            "z": 1,
            "elements": [
                "botania:quartztypemana@2"
            ]
        },
        {
            "x": -2,
            "y": 0,
            "z": 2,
            "elements": [
                "botania:quartztypemana@0"
            ]
        },
        {
            "x": 4,
            "y": 0,
            "z": 0,
            "elements": [
                "botania:quartzslabmanahalf@0"
            ]
        },
        {
            "x": -5,
            "y": 5,
            "z": 1,
            "elements": [
                "botania:quartzstairsmana@4"
            ]
        },
        {
            "x": 0,
            "y": 4,
            "z": 5,
            "elements": [
                "botania:managlasspane@0"
            ]
        },
        {
            "x": -2,
            "y": 1,
            "z": 2,
            "elements": [
                "botania:managlasspane@0"
            ]
        },
        {
            "x": 1,
            "y": 0,
            "z": 1,
            "elements": [
                "modularmachinery:blockinputbus"
            ]
        },
        {
            "x": 0,
            "y": 1,
            "z": 4,
            "elements": [
                "botania:quartztypemana@2"
            ]
        },
        {
            "x": -1,
            "y": 0,
            "z": 8,
            "elements": [
                "botania:quartzstairsmana@3"
            ]
        },
        {
            "x": -1,
            "y": 7,
            "z": 3,
            "elements": [
                "botania:quartztypemana@0"
            ]
        },
        {
            "x": -2,
            "y": 6,
            "z": 1,
            "elements": [
                "botania:quartzslabmanahalf@0"
            ]
        },
        {
            "x": -3,
            "y": 6,
            "z": 2,
            "elements": [
                "botania:quartzslabmanahalf@0"
            ]
        },
        {
            "x": 4,
            "y": 2,
            "z": 1,
            "elements": [
                "botania:quartztypemana@2"
            ]
        },
        {
            "x": 4,
            "y": 1,
            "z": 7,
            "elements": [
                "botania:quartztypemana@2"
            ]
        },
        {
            "x": 3,
            "y": 6,
            "z": 6,
            "elements": [
                "botania:quartzslabmanahalf@0"
            ]
        },
        {
            "x": 3,
            "y": 5,
            "z": -1,
            "elements": [
                "botania:quartzstairsmana@6"
            ]
        },
        {
            "x": 0,
            "y": 2,
            "z": 4,
            "elements": [
                "botania:managlasspane@0"
            ]
        },
        {
            "x": 3,
            "y": 0,
            "z": 4,
            "elements": [
                "botania:quartztypemana@1"
            ]
        },
        {
            "x": 0,
            "y": 3,
            "z": 5,
            "elements": [
                "botania:managlasspane@0"
            ]
        },
        {
            "x": 3,
            "y": 4,
            "z": 7,
            "elements": [
                "botania:quartzslabmanahalf@8"
            ]
        },
        {
            "x": 5,
            "y": 6,
            "z": 3,
            "elements": [
                "botania:quartzstairsmana@1"
            ]
        },
        {
            "x": 0,
            "y": 6,
            "z": 7,
            "elements": [
                "botania:quartzslabmanahalf@8"
            ]
        },
        {
            "x": -3,
            "y": 0,
            "z": 4,
            "elements": [
                "botania:quartztypemana@1"
            ]
        },
        {
            "x": 4,
            "y": 0,
            "z": 1,
            "elements": [
                "botania:quartztypemana@2"
            ]
        },
        {
            "x": -3,
            "y": 6,
            "z": 4,
            "elements": [
                "botania:quartzslabmanahalf@8"
            ]
        },
        {
            "x": 2,
            "y": 0,
            "z": 5,
            "elements": [
                "botania:quartztypemana@0"
            ]
        },
        {
            "x": 4,
            "y": 0,
            "z": 6,
            "elements": [
                "botania:quartzstairsmana@1"
            ]
        },
        {
            "x": 0,
            "y": 7,
            "z": 7,
            "elements": [
                "botania:quartzslabmanahalf@0"
            ]
        },
        {
            "x": 3,
            "y": 5,
            "z": 7,
            "elements": [
                "botania:quartztypemana@0"
            ]
        },
        {
            "x": -4,
            "y": 6,
            "z": 2,
            "elements": [
                "botania:quartzstairsmana@0"
            ]
        },
        {
            "x": 0,
            "y": 5,
            "z": 5,
            "elements": [
                "botania:managlasspane@0"
            ]
        },
        {
            "x": -2,
            "y": 6,
            "z": 6,
            "elements": [
                "botania:quartzslabmanahalf@8"
            ]
        },
        {
            "x": -2,
            "y": 2,
            "z": 2,
            "elements": [
                "botania:pylon@1"
            ]
        },
        {
            "x": 4,
            "y": 1,
            "z": 1,
            "elements": [
                "botania:quartztypemana@2"
            ]
        },
        {
            "x": 0,
            "y": 0,
            "z": 4,
            "elements": [
                "botania:quartztypemana@1"
            ]
        },
        {
            "x": -1,
            "y": 0,
            "z": 2,
            "elements": [
                "botania:quartztypemana@0"
            ]
        },
        {
            "x": -2,
            "y": 0,
            "z": 0,
            "elements": [
                "botania:quartzstairsmana@2"
            ]
        },
        {
            "x": 4,
            "y": 6,
            "z": 3,
            "elements": [
                "botania:quartzslabmanahalf@0"
            ]
        },
        {
            "x": -4,
            "y": 0,
            "z": 2,
            "elements": [
                "botania:quartzstairsmana@0"
            ]
        },
        {
            "x": -1,
            "y": 6,
            "z": 7,
            "elements": [
                "botania:quartzslabmanahalf@8"
            ]
        },
        {
            "x": -2,
            "y": 5,
            "z": 9,
            "elements": [
                "botania:quartzslabmanahalf@8"
            ]
        },
        {
            "x": 0,
            "y": 6,
            "z": 4,
            "elements": [
                "botania:managlasspane@0"
            ]
        },
        {
            "x": -2,
            "y": 6,
            "z": 2,
            "elements": [
                "botania:quartzslabmanahalf@8"
            ]
        },
        {
            "x": -1,
            "y": 0,
            "z": 5,
            "elements": [
                "botania:quartztypemana@0"
            ]
        },
        {
            "x": 1,
            "y": 7,
            "z": 6,
            "elements": [
                "botania:quartzstairsmana@1"
            ]
        },
        {
            "x": 0,
            "y": 6,
            "z": -1,
            "elements": [
                "botania:quartzstairsmana@2"
            ]
        },
        {
            "x": -3,
            "y": 0,
            "z": 8,
            "elements": [
                "botania:quartztypemana@2"
            ]
        },
        {
            "x": 0,
            "y": 8,
            "z": 6,
            "elements": [
                "botania:quartzslabmanahalf@0"
            ]
        },
        {
            "x": 1,
            "y": 7,
            "z": 3,
            "elements": [
                "botania:quartztypemana@0"
            ]
        },
        {
            "x": -1,
            "y": 6,
            "z": 0,
            "elements": [
                "botania:quartzslabmanahalf@0"
            ]
        },
        {
            "x": 0,
            "y": 7,
            "z": 5,
            "elements": [
                "botania:quartztypemana@1"
            ]
        },
        {
            "x": 3,
            "y": 0,
            "z": 7,
            "elements": [
                "botania:quartztypemana@0"
            ]
        },
        {
            "x": -3,
            "y": 7,
            "z": 4,
            "elements": [
                "botania:quartzslabmanahalf@0"
            ]
        },
        {
            "x": -5,
            "y": 6,
            "z": 2,
            "elements": [
                "botania:quartzstairsmana@2"
            ]
        },
        {
            "x": 0,
            "y": 5,
            "z": 4,
            "elements": [
                "botania:managlass@0"
            ]
        },
        {
            "x": -2,
            "y": 6,
            "z": 9,
            "elements": [
                "botania:quartzstairsmana@0"
            ]
        },
        {
            "x": 1,
            "y": 8,
            "z": 3,
            "elements": [
                "botania:quartzslabmanahalf@0"
            ]
        },
        {
            "x": 2,
            "y": 6,
            "z": 7,
            "elements": [
                "botania:quartzslabmanahalf@0"
            ]
        },
        {
            "x": -5,
            "y": 5,
            "z": 2,
            "elements": [
                "botania:quartzslabmanahalf@8"
            ]
        },
        {
            "x": 0,
            "y": 3,
            "z": 4,
            "elements": [
                "botania:managlass@0"
            ]
        },
        {
            "x": 3,
            "y": 6,
            "z": 3,
            "elements": [
                "botania:quartzslabmanahalf@8"
            ]
        },
        {
            "x": -2,
            "y": 8,
            "z": 4,
            "elements": [
                "botania:quartzslabmanahalf@0"
            ]
        },
        {
            "x": -4,
            "y": 0,
            "z": 5,
            "elements": [
                "botania:quartzstairsmana@0"
            ]
        },
        {
            "x": 0,
            "y": 7,
            "z": 6,
            "elements": [
                "botania:quartztypemana@1"
            ]
        },
        {
            "x": -4,
            "y": 0,
            "z": 8,
            "elements": [
                "botania:quartzslabmanahalf@0"
            ]
        },
        {
            "x": 5,
            "y": 5,
            "z": 7,
            "elements": [
                "botania:quartzstairsmana@5"
            ]
        },
        {
            "x": 2,
            "y": 7,
            "z": 3,
            "elements": [
                "botania:quartzstairsmana@2"
            ]
        },
        {
            "x": 2,
            "y": 6,
            "z": 0,
            "elements": [
                "botania:quartzstairsmana@2"
            ]
        },
        {
            "x": -2,
            "y": 7,
            "z": 4,
            "elements": [
                "botania:quartztypemana@1"
            ]
        },
        {
            "x": 0,
            "y": 4,
            "z": 4,
            "elements": [
                "botania:managlass@0"
            ]
        },
        {
            "x": 1,
            "y": 0,
            "z": 2,
            "elements": [
                "botania:quartztypemana@0"
            ]
        },
        {
            "x": 1,
            "y": 6,
            "z": 1,
            "elements": [
                "botania:quartzslabmanahalf@8"
            ]
        },
        {
            "x": 3,
            "y": 6,
            "z": 5,
            "elements": [
                "botania:quartzslabmanahalf@8"
            ]
        },
        {
            "x": -3,
            "y": 0,
            "z": 1,
            "elements": [
                "botania:quartztypemana@0"
            ]
        },
        {
            "x": -4,
            "y": 0,
            "z": 4,
            "elements": [
                "botania:quartztypemana@1"
            ]
        },
        {
            "x": 2,
            "y": 1,
            "z": 2,
            "elements": [
                "botania:managlasspane@0"
            ]
        },
        {
            "x": 0,
            "y": 9,
            "z": 5,
            "elements": [
                "botania:quartzstairsmana@3"
            ]
        },
        {
            "x": -3,
            "y": 3,
            "z": 8,
            "elements": [
                "botania:quartztypemana@2"
            ]
        },
        {
            "x": 3,
            "y": 0,
            "z": 6,
            "elements": [
                "botania:quartztypemana@0"
            ]
        },
        {
            "x": 4,
            "y": 0,
            "z": 3,
            "elements": [
                "botania:quartzstairsmana@1"
            ]
        },
        {
            "x": 1,
            "y": 0,
            "z": 7,
            "elements": [
                "botania:quartztypemana@0"
            ]
        },
        {
            "x": 3,
            "y": 0,
            "z": 8,
            "elements": [
                "botania:quartztypemana@2"
            ]
        },
        {
            "x": -1,
            "y": 0,
            "z": 4,
            "elements": [
                "modularmachinery:blockmanaproviderinput@0",
                "gugu-utils:sparkmanahatch"
            ]
        },
        {
            "x": -3,
            "y": 4,
            "z": 8,
            "elements": [
                "botania:quartztypemana@2"
            ]
        },
        {
            "x": 1,
            "y": 8,
            "z": 5,
            "elements": [
                "botania:quartzslabmanahalf@0"
            ]
        },
        {
            "x": 2,
            "y": 0,
            "z": 2,
            "elements": [
                "botania:quartztypemana@0"
            ]
        },
        {
            "x": -3,
            "y": 1,
            "z": 8,
            "elements": [
                "botania:quartztypemana@2"
            ]
        },
        {
            "x": 4,
            "y": 5,
            "z": 0,
            "elements": [
                "botania:quartzslabmanahalf@8"
            ]
        },
        {
            "x": 4,
            "y": 6,
            "z": 5,
            "elements": [
                "botania:quartzslabmanahalf@0"
            ]
        },
        {
            "x": 0,
            "y": 0,
            "z": 6,
            "elements": [
                "botania:quartztypemana@1"
            ]
        },
        {
            "x": -1,
            "y": 6,
            "z": -1,
            "elements": [
                "botania:quartzstairsmana@2"
            ]
        },
        {
            "x": 0,
            "y": 0,
            "z": 1,
            "elements": [
                "botania:quartztypemana@1"
            ]
        },
        {
            "x": -3,
            "y": 2,
            "z": 8,
            "elements": [
                "botania:quartztypemana@2"
            ]
        },
        {
            "x": 1,
            "y": 7,
            "z": 5,
            "elements": [
                "botania:quartztypemana@0"
            ]
        },
        {
            "x": 2,
            "y": 2,
            "z": 2,
            "elements": [
                "botania:pylon@0"
            ]
        },
        {
            "x": 1,
            "y": 0,
            "z": 3,
            "elements": [
                "botania:quartztypemana@0"
            ]
        },
        {
            "x": -1,
            "y": 7,
            "z": 2,
            "elements": [
                "botania:quartzstairsmana@0"
            ]
        },
        {
            "x": -1,
            "y": 6,
            "z": 1,
            "elements": [
                "botania:quartzslabmanahalf@8"
            ]
        },
        {
            "x": 4,
            "y": 6,
            "z": 7,
            "elements": [
                "botania:quartzstairsmana@3"
            ]
        },
        {
            "x": 0,
            "y": 8,
            "z": 5,
            "elements": [
                "botania:quartztypemana@1"
            ]
        },
        {
            "x": 3,
            "y": 5,
            "z": 0,
            "elements": [
                "botania:quartzstairsmana@5"
            ]
        },
        {
            "x": -1,
            "y": 0,
            "z": 1,
            "elements": [
                "modularmachinery:blockoutputbus"
            ]
        },
        {
            "x": 4,
            "y": 4,
            "z": 7,
            "elements": [
                "botania:quartztypemana@2"
            ]
        },
        {
            "x": -3,
            "y": 5,
            "z": 1,
            "elements": [
                "botania:quartztypemana@0"
            ]
        },
        {
            "x": 4,
            "y": 5,
            "z": 8,
            "elements": [
                "botania:quartzslabmanahalf@8"
            ]
        },
        {
            "x": 2,
            "y": 6,
            "z": 2,
            "elements": [
                "botania:quartzslabmanahalf@8"
            ]
        },
        {
            "x": 3,
            "y": 0,
            "z": 5,
            "elements": [
                "botania:quartztypemana@0"
            ]
        },
        {
            "x": 4,
            "y": 5,
            "z": 7,
            "elements": [
                "botania:quartzstairsmana@5"
            ]
        },
        {
            "x": -4,
            "y": 6,
            "z": 1,
            "elements": [
                "botania:quartzstairsmana@2"
            ]
        },
        {
            "x": 3,
            "y": 6,
            "z": 0,
            "elements": [
                "botania:quartzstairsmana@1"
            ]
        },
        {
            "x": -3,
            "y": 5,
            "z": -1,
            "elements": [
                "botania:quartzstairsmana@6"
            ]
        },
        {
            "x": -3,
            "y": 4,
            "z": 1,
            "elements": [
                "botania:quartzslabmanahalf@8"
            ]
        },
        {
            "x": -4,
            "y": 6,
            "z": 4,
            "elements": [
                "botania:quartzslabmanafull@0"
            ]
        },
        {
            "x": -3,
            "y": 6,
            "z": 6,
            "elements": [
                "botania:quartzslabmanahalf@0"
            ]
        },
        {
            "x": 5,
            "y": 5,
            "z": 2,
            "elements": [
                "botania:quartzslabmanahalf@8"
            ]
        },
        {
            "x": -1,
            "y": 8,
            "z": 5,
            "elements": [
                "botania:quartzslabmanahalf@0"
            ]
        },
        {
            "x": -2,
            "y": 0,
            "z": 1,
            "elements": [
                "botania:quartztypemana@0"
            ]
        },
        {
            "x": -3,
            "y": 6,
            "z": 8,
            "elements": [
                "botania:quartzstairsmana@0"
            ]
        },
        {
            "x": -2,
            "y": 6,
            "z": 7,
            "elements": [
                "botania:quartzslabmanahalf@0"
            ]
        },
        {
            "x": -4,
            "y": 5,
            "z": 1,
            "elements": [
                "botania:quartzstairsmana@6"
            ]
        },
        {
            "x": -3,
            "y": 5,
            "z": 8,
            "elements": [
                "botania:quartzstairsmana@7"
            ]
        },
        {
            "x": 4,
            "y": 2,
            "z": 7,
            "elements": [
                "botania:quartztypemana@2"
            ]
        },
        {
            "x": -4,
            "y": 4,
            "z": 1,
            "elements": [
                "botania:quartztypemana@2"
            ]
        },
        {
            "x": 2,
            "y": 7,
            "z": 5,
            "elements": [
                "botania:quartzstairsmana@3"
            ]
        },
        {
            "x": 5,
            "y": 6,
            "z": 2,
            "elements": [
                "botania:quartzstairsmana@1"
            ]
        },
        {
            "x": 4,
            "y": 3,
            "z": 7,
            "elements": [
                "botania:quartztypemana@2"
            ]
        },
        {
            "x": 4,
            "y": 6,
            "z": 6,
            "elements": [
                "botania:quartzstairsmana@1"
            ]
        },
        {
            "x": -1,
            "y": 7,
            "z": 5,
            "elements": [
                "botania:quartztypemana@0"
            ]
        },
        {
            "x": -3,
            "y": 6,
            "z": 1,
            "elements": [
                "botania:quartzstairsmana@0"
            ]
        },
        {
            "x": 0,
            "y": 0,
            "z": 8,
            "elements": [
                "botania:quartztypemana@1"
            ]
        },
        {
            "x": -5,
            "y": 6,
            "z": 4,
            "elements": [
                "botania:quartzstairsmana@0"
            ]
        },
        {
            "x": -2,
            "y": 7,
            "z": 3,
            "elements": [
                "botania:quartzstairsmana@2"
            ]
        },
        {
            "x": 4,
            "y": 0,
            "z": 7,
            "elements": [
                "botania:quartztypemana@2"
            ]
        },
        {
            "x": -2,
            "y": 0,
            "z": 4,
            "elements": [
                "botania:quartztypemana@1"
            ]
        },
        {
            "x": -4,
            "y": 0,
            "z": 0,
            "elements": [
                "botania:quartzslabmanahalf@0"
            ]
        },
        {
            "x": 5,
            "y": 6,
            "z": 5,
            "elements": [
                "botania:quartzstairsmana@1"
            ]
        },
        {
            "x": -1,
            "y": 8,
            "z": 4,
            "elements": [
                "botania:quartztypemana@1"
            ]
        },
        {
            "x": -2,
            "y": 6,
            "z": 8,
            "elements": [
                "botania:quartzstairsmana@3"
            ]
        },
        {
            "x": -3,
            "y": 0,
            "z": 7,
            "elements": [
                "botania:quartztypemana@0"
            ]
        },
        {
            "x": -2,
            "y": 2,
            "z": 6,
            "elements": [
                "botania:pylon@0"
            ]
        },
        {
            "x": 3,
            "y": 2,
            "z": 0,
            "elements": [
                "botania:quartztypemana@2"
            ]
        },
        {
            "x": 1,
            "y": 0,
            "z": 5,
            "elements": [
                "botania:quartztypemana@0"
            ]
        },
        {
            "x": -1,
            "y": 0,
            "z": 6,
            "elements": [
                "botania:quartztypemana@0"
            ]
        },
        {
            "x": 1,
            "y": 6,
            "z": 0,
            "elements": [
                "botania:quartzslabmanahalf@0"
            ]
        },
        {
            "x": 4,
            "y": 6,
            "z": 2,
            "elements": [
                "botania:quartzstairsmana@2"
            ]
        },
        {
            "x": 3,
            "y": 5,
            "z": 1,
            "elements": [
                "botania:quartztypemana@0"
            ]
        },
        {
            "x": -2,
            "y": 6,
            "z": -1,
            "elements": [
                "botania:quartzstairsmana@2"
            ]
        },
        {
            "x": -4,
            "y": 2,
            "z": 1,
            "elements": [
                "botania:quartztypemana@2"
            ]
        },
        {
            "x": -2,
            "y": 7,
            "z": 5,
            "elements": [
                "botania:quartzstairsmana@3"
            ]
        },
        {
            "x": -1,
            "y": 7,
            "z": 4,
            "elements": [
                "botania:quartztypemana@1"
            ]
        },
        {
            "x": -4,
            "y": 2,
            "z": 7,
            "elements": [
                "botania:quartztypemana@2"
            ]
        },
        {
            "x": 3,
            "y": 4,
            "z": 1,
            "elements": [
                "botania:quartzslabmanahalf@8"
            ]
        },
        {
            "x": 3,
            "y": 1,
            "z": 0,
            "elements": [
                "botania:quartztypemana@2"
            ]
        },
        {
            "x": 0,
            "y": 0,
            "z": 3,
            "elements": [
                "modularmachinery:blockmanaproviderinput@0",
                "gugu-utils:sparkmanahatch"
            ]
        },
        {
            "x": -4,
            "y": 3,
            "z": 1,
            "elements": [
                "botania:quartztypemana@2"
            ]
        },
        {
            "x": -3,
            "y": 0,
            "z": 0,
            "elements": [
                "botania:quartztypemana@2"
            ]
        },
        {
            "x": -4,
            "y": 0,
            "z": 1,
            "elements": [
                "botania:quartztypemana@2"
            ]
        },
        {
            "x": 5,
            "y": 6,
            "z": 4,
            "elements": [
                "botania:quartzstairsmana@1"
            ]
        },
        {
            "x": -3,
            "y": 5,
            "z": 9,
            "elements": [
                "botania:quartzstairsmana@7"
            ]
        },
        {
            "x": -5,
            "y": 6,
            "z": 6,
            "elements": [
                "botania:quartzstairsmana@3"
            ]
        },
        {
            "x": -3,
            "y": 6,
            "z": 3,
            "elements": [
                "botania:quartzslabmanahalf@8"
            ]
        },
        {
            "x": 3,
            "y": 6,
            "z": 8,
            "elements": [
                "botania:quartzstairsmana@3"
            ]
        },
        {
            "x": -2,
            "y": 0,
            "z": 7,
            "elements": [
                "botania:quartztypemana@0"
            ]
        },
        {
            "x": -2,
            "y": 5,
            "z": -1,
            "elements": [
                "botania:quartzslabmanahalf@8"
            ]
        },
        {
            "x": 3,
            "y": 6,
            "z": 2,
            "elements": [
                "botania:quartzslabmanahalf@0"
            ]
        },
        {
            "x": 3,
            "y": 4,
            "z": 0,
            "elements": [
                "botania:quartztypemana@2"
            ]
        },
        {
            "x": 0,
            "y": 6,
            "z": 0,
            "elements": [
                "botania:quartzslabmanafull@0"
            ]
        },
        {
            "x": -4,
            "y": 1,
            "z": 1,
            "elements": [
                "botania:quartztypemana@2"
            ]
        },
        {
            "x": 3,
            "y": 5,
            "z": 8,
            "elements": [
                "botania:quartzstairsmana@7"
            ]
        },
        {
            "x": 2,
            "y": 0,
            "z": 8,
            "elements": [
                "botania:quartzstairsmana@3"
            ]
        },
        {
            "x": -4,
            "y": 0,
            "z": 6,
            "elements": [
                "botania:quartzstairsmana@0"
            ]
        },
        {
            "x": 3,
            "y": 6,
            "z": 1,
            "elements": [
                "botania:quartzstairsmana@2"
            ]
        },
        {
            "x": -5,
            "y": 5,
            "z": 7,
            "elements": [
                "botania:quartzstairsmana@4"
            ]
        },
        {
            "x": -3,
            "y": 0,
            "z": 3,
            "elements": [
                "botania:quartztypemana@0"
            ]
        },
        {
            "x": 3,
            "y": 3,
            "z": 0,
            "elements": [
                "botania:quartztypemana@2"
            ]
        },
        {
            "x": -1,
            "y": 9,
            "z": 4,
            "elements": [
                "botania:quartzstairsmana@0"
            ]
        },
        {
            "x": -3,
            "y": 2,
            "z": 0,
            "elements": [
                "botania:quartztypemana@2"
            ]
        },
        {
            "x": -1,
            "y": 3,
            "z": 4,
            "elements": [
                "botania:managlasspane@0"
            ]
        },
        {
            "x": 0,
            "y": 6,
            "z": 8,
            "elements": [
                "botania:quartzslabmanafull@0"
            ]
        },
        {
            "x": 3,
            "y": 4,
            "z": 8,
            "elements": [
                "botania:quartztypemana@2"
            ]
        },
        {
            "x": 3,
            "y": 3,
            "z": 8,
            "elements": [
                "botania:quartztypemana@2"
            ]
        },
        {
            "x": -3,
            "y": 0,
            "z": 6,
            "elements": [
                "botania:quartztypemana@0"
            ]
        },
        {
            "x": 0,
            "y": 7,
            "z": 1,
            "elements": [
                "botania:quartzslabmanahalf@0"
            ]
        },
        {
            "x": -4,
            "y": 6,
            "z": 3,
            "elements": [
                "botania:quartzslabmanahalf@0"
            ]
        },
        {
            "x": 3,
            "y": 0,
            "z": 1,
            "elements": [
                "botania:quartztypemana@0"
            ]
        },
        {
            "x": -5,
            "y": 5,
            "z": 6,
            "elements": [
                "botania:quartzslabmanahalf@8"
            ]
        },
        {
            "x": -1,
            "y": 4,
            "z": 4,
            "elements": [
                "botania:managlasspane@0"
            ]
        },
        {
            "x": 4,
            "y": 0,
            "z": 2,
            "elements": [
                "botania:quartzstairsmana@1"
            ]
        },
        {
            "x": -2,
            "y": 0,
            "z": 3,
            "elements": [
                "botania:quartztypemana@0"
            ]
        },
        {
            "x": 1,
            "y": 0,
            "z": 4,
            "elements": [
                "modularmachinery:blockmanaproviderinput@0",
                "gugu-utils:sparkmanahatch"
            ]
        },
        {
            "x": 0,
            "y": 6,
            "z": 1,
            "elements": [
                "botania:quartzslabmanahalf@8"
            ]
        },
        {
            "x": 1,
            "y": 6,
            "z": 8,
            "elements": [
                "botania:quartzslabmanahalf@0"
            ]
        },
        {
            "x": 3,
            "y": 0,
            "z": 0,
            "elements": [
                "botania:quartztypemana@2"
            ]
        },
        {
            "x": 3,
            "y": 5,
            "z": 9,
            "elements": [
                "botania:quartzstairsmana@7"
            ]
        },
        {
            "x": -1,
            "y": 5,
            "z": 4,
            "elements": [
                "botania:managlasspane@0"
            ]
        },
        {
            "x": -2,
            "y": 0,
            "z": 6,
            "elements": [
                "botania:quartztypemana@0"
            ]
        },
        {
            "x": 2,
            "y": 0,
            "z": 1,
            "elements": [
                "botania:quartztypemana@0"
            ]
        },
        {
            "x": 0,
            "y": 8,
            "z": 2,
            "elements": [
                "botania:quartzslabmanahalf@0"
            ]
        },
        {
            "x": -3,
            "y": 4,
            "z": 0,
            "elements": [
                "botania:quartztypemana@2"
            ]
        },
        {
            "x": 1,
            "y": 6,
            "z": -1,
            "elements": [
                "botania:quartzstairsmana@2"
            ]
        },
        {
            "x": -5,
            "y": 6,
            "z": 3,
            "elements": [
                "botania:quartzstairsmana@0"
            ]
        },
        {
            "x": 4,
            "y": 0,
            "z": 5,
            "elements": [
                "botania:quartzstairsmana@1"
            ]
        },
        {
            "x": -3,
            "y": 4,
            "z": 7,
            "elements": [
                "botania:quartzslabmanahalf@8"
            ]
        },
        {
            "x": 3,
            "y": 1,
            "z": 8,
            "elements": [
                "botania:quartztypemana@2"
            ]
        },
        {
            "x": -3,
            "y": 1,
            "z": 0,
            "elements": [
                "botania:quartztypemana@2"
            ]
        },
        {
            "x": 0,
            "y": 0,
            "z": 7,
            "elements": [
                "botania:quartztypemana@1"
            ]
        },
        {
            "x": -1,
            "y": 0,
            "z": 3,
            "elements": [
                "botania:quartztypemana@0"
            ]
        },
        {
            "x": -3,
            "y": 3,
            "z": 0,
            "elements": [
                "botania:quartztypemana@2"
            ]
        },
        {
            "x": 4,
            "y": 0,
            "z": 8,
            "elements": [
                "botania:quartzslabmanahalf@0"
            ]
        },
        {
            "x": -3,
            "y": 5,
            "z": 7,
            "elements": [
                "botania:quartztypemana@0"
            ]
        },
        {
            "x": 3,
            "y": 2,
            "z": 8,
            "elements": [
                "botania:quartztypemana@2"
            ]
        },
        {
            "x": 2,
            "y": 0,
            "z": 4,
            "elements": [
                "botania:quartztypemana@1"
            ]
        },
        {
            "x": -2,
            "y": 1,
            "z": 6,
            "elements": [
                "botania:managlasspane@0"
            ]
        },
        {
            "x": 1,
            "y": 7,
            "z": 2,
            "elements": [
                "botania:quartzstairsmana@1"
            ]
        }
    ]}