{
    "registryname":"internal_combustion_engine",
    "localizedname":"内燃发电机",
    "failure-action": "still",
    "requires-blueprint": false,
    "has-factory": true,
    "factory-only": true,
    "color":"343434",
    "parts": [
        {
            "x": 0,
            "y": 0,
            "z": 0,
           "elements": [
                "modularmachinery:blockcontroller@2"
            ]
        },
        {
            "x": -1,
            "y": 0,
            "z": 1,
            "elements": [
                "immersiveengineering:metal_decoration0@5"
            ]
        },
        {
            "x": 2,
            "y": 0,
            "z": 0,
            "elements": [
                "immersiveengineering:metal_decoration0@6",
                "modularmachinery:blockenergyoutputhatch"
            ]
        },
        {
            "x": -2,
            "y": 0,
            "z": 2,
            "elements": [
                "immersiveengineering:metal_decoration0@7"
            ]
        },
        {
            "x": -2,
            "y": -1,
            "z": 0,
            "elements": [
                "immersiveengineering:metal_decoration0@7"
            ]
        },
        {
            "x": -2,
            "y": -1,
            "z": 2,
            "elements": [
                "immersiveengineering:metal_decoration0@7"
            ]
        },
        {
            "x": -2,
            "y": 1,
            "z": 2,
            "elements": [
                "immersiveengineering:metal_decoration0@7"
            ]
        },
        {
            "x": 2,
            "y": -1,
            "z": 2,
           "elements": [
                "modularmachinery:blockfluidinputhatch",
                "immersiveengineering:metal_device1@6"
            ]
        },
        {
            "x": 0,
            "y": 1,
            "z": 2,
            "elements": [
                "immersiveengineering:metal_decoration0@5"
            ]
        },
        {
            "x": 1,
            "y": 0,
            "z": 1,
            "elements": [
                "immersiveengineering:metal_decoration0@5"
            ]
        },
        {
            "x": 1,
            "y": -1,
            "z": 1,
           "elements": [
                "immersiveengineering:metal_device1@6"
            ]
        },
        {
            "x": 0,
            "y": -1,
            "z": 0,
            "elements": [
                "immersiveengineering:metal_decoration1@1",
                "modularmachinery:blockinputbus@0"

            ]
        },
        {
            "x": -1,
            "y": -1,
            "z": 1,
           "elements": [
                "immersiveengineering:metal_device1@6"
            ]
        },
        {
            "x": 0,
            "y": -1,
            "z": 2,
            "elements": [
                "immersiveengineering:metal_decoration1@1"
            ]
        },
        {
            "x": 1,
            "y": 1,
            "z": 1,
            "elements": [
                "immersiveengineering:metal_decoration0@5"
            ]
        },
        {
            "x": 0,
            "y": 0,
            "z": 2,
            "elements": [
                "immersiveengineering:metal_decoration0@5"
            ]
        },
        {
            "x": -1,
            "y": 1,
            "z": 1,
            "elements": [
                "immersiveengineering:metal_decoration0@5"
            ]
        },
        {
            "x": 1,
            "y": 0,
            "z": 0,
            "elements": [
                "immersiveengineering:metal_decoration0@5"
            ]
        },
        {
            "x": 2,
            "y": 0,
            "z": 2,
            "elements": [
                "immersiveengineering:metal_decoration0@6",
                "modularmachinery:blockenergyoutputhatch"
            ]
        },
        {
            "x": -1,
            "y": 0,
            "z": 0,
            "elements": [
                "immersiveengineering:metal_decoration0@5"
            ]
        },
        {
            "x": -2,
            "y": 0,
            "z": 1,
            "elements": [
                "immersiveengineering:metal_decoration0@7"
            ]
        },
        {
            "x": 2,
            "y": 0,
            "z": 1,
            "elements": [
                "immersiveengineering:metal_decoration0@6",
                "modularmachinery:blockenergyoutputhatch"
            ]
        },
        {
            "x": 0,
            "y": 1,
            "z": 0,
            "elements": [
                "immersiveengineering:metal_decoration0@5"
            ]
        },
        {
            "x": 1,
            "y": -1,
            "z": 2,
            "elements": [
                "immersiveengineering:metal_decoration1@1"
            ]
        },
        {
            "x": 1,
            "y": -1,
            "z": 0,
            "elements": [
                "immersiveengineering:metal_decoration1@1"
            ]
        },
        {
            "x": -1,
            "y": -1,
            "z": 0,
            "elements": [
                "immersiveengineering:metal_decoration1@1"
            ]
        },
        {
            "x": 2,
            "y": -1,
            "z": 0,
           "elements": [
                "modularmachinery:blockfluidinputhatch",
                "immersiveengineering:metal_device1@6"
            ]
        },
        {
            "x": 0,
            "y": 0,
            "z": 1,
            "elements": [
                "immersiveengineering:metal_decoration0@5"
            ]
        },
        {
            "x": -2,
            "y": 1,
            "z": 0,
            "elements": [
                "immersiveengineering:metal_decoration0@7"
            ]
        },
        {
            "x": 0,
            "y": -1,
            "z": 1,
           "elements": [
                "immersiveengineering:metal_device1@6"
            ]
        },
        {
            "x": -1,
            "y": -1,
            "z": 2,
            "elements": [
                "immersiveengineering:metal_decoration1@1"
            ]
        },
        {
            "x": -2,
            "y": -1,
            "z": 1,
            "elements": [
                "immersiveengineering:metal_decoration0@7"
            ]
        },
        {
            "x": -2,
            "y": 0,
            "z": 0,
            "elements": [
                "immersiveengineering:metal_decoration0@7"
            ]
        },
        {
            "x": 2,
            "y": -1,
            "z": 1,
            "elements": [
                "immersiveengineering:metal_decoration0@6",
                "modularmachinery:blockenergyoutputhatch"
            ]
        },
        {
            "x": -1,
            "y": 0,
            "z": 2,
            "elements": [
                "immersiveengineering:metal_decoration0@5"
            ]
        },
        {
            "x": 0,
            "y": 1,
            "z": 1,
            "elements": [
                "immersiveengineering:metal_decoration0@5"
            ]
        },
        {
            "x": 1,
            "y": 0,
            "z": 2,
            "elements": [
                "immersiveengineering:metal_decoration0@5"
            ]
        },
        {
            "x": -2,
            "y": 1,
            "z": 1,
            "elements": [
                "immersiveengineering:metal_decoration0@7"
            ]
        }
    ]}